2025-08-11 10:51:37,877 | src.biotech_pipeline.agents.search_agent | ERROR | Model execution error: Logger._log() got an unexpected keyword argument 'quality_score'
2025-08-11 10:51:37,877 | src.biotech_pipeline.agents.search_agent | ERROR | AI extraction failed for Ezymind Healthcare Pvt Ltd: Model execution failed: Logger._log() got an unexpected keyword argument 'quality_score'
2025-08-11 10:54:06,806 | src.biotech_pipeline.pipeline.etl_orchestrator | CRITICAL | Unexpected error for BIRAC/KIIT02236/BIG-23/23: WebExtractor.extract() takes 2 positional arguments but 3 were given
Traceback (most recent call last):
  File "/Users/kaushalprajapati/Desktop/Development/BiD_Indian_BT_startups/src/biotech_pipeline/pipeline/etl_orchestrator.py", line 55, in run
    birac_data = self.birac_extractor.extract(bid, ai_profile["website_url"])
                 ^^^^^^^^^^^^^^^^^^^^^^^^^^^^^^^^^^^^^^^^^^^^^^^^^^^^^^^^^^^^
TypeError: WebExtractor.extract() takes 2 positional arguments but 3 were given
2025-08-11 10:54:33,505 | src.biotech_pipeline.pipeline.etl_orchestrator | CRITICAL | Unexpected error for BIRAC/SINE0709/BIG-23/23: WebExtractor.extract() takes 2 positional arguments but 3 were given
Traceback (most recent call last):
  File "/Users/kaushalprajapati/Desktop/Development/BiD_Indian_BT_startups/src/biotech_pipeline/pipeline/etl_orchestrator.py", line 55, in run
    birac_data = self.birac_extractor.extract(bid, ai_profile["website_url"])
                 ^^^^^^^^^^^^^^^^^^^^^^^^^^^^^^^^^^^^^^^^^^^^^^^^^^^^^^^^^^^^
TypeError: WebExtractor.extract() takes 2 positional arguments but 3 were given
2025-08-11 10:55:03,926 | src.biotech_pipeline.pipeline.etl_orchestrator | CRITICAL | Unexpected error for BIRAC/SIIC0882/BIG-22/23: WebExtractor.extract() takes 2 positional arguments but 3 were given
Traceback (most recent call last):
  File "/Users/kaushalprajapati/Desktop/Development/BiD_Indian_BT_startups/src/biotech_pipeline/pipeline/etl_orchestrator.py", line 55, in run
    birac_data = self.birac_extractor.extract(bid, ai_profile["website_url"])
                 ^^^^^^^^^^^^^^^^^^^^^^^^^^^^^^^^^^^^^^^^^^^^^^^^^^^^^^^^^^^^
TypeError: WebExtractor.extract() takes 2 positional arguments but 3 were given
2025-08-11 10:55:31,941 | src.biotech_pipeline.pipeline.etl_orchestrator | CRITICAL | Unexpected error for BIRAC/IKP01696/BIG-22/23: WebExtractor.extract() takes 2 positional arguments but 3 were given
Traceback (most recent call last):
  File "/Users/kaushalprajapati/Desktop/Development/BiD_Indian_BT_startups/src/biotech_pipeline/pipeline/etl_orchestrator.py", line 55, in run
    birac_data = self.birac_extractor.extract(bid, ai_profile["website_url"])
                 ^^^^^^^^^^^^^^^^^^^^^^^^^^^^^^^^^^^^^^^^^^^^^^^^^^^^^^^^^^^^
TypeError: WebExtractor.extract() takes 2 positional arguments but 3 were given
2025-08-11 11:02:21,490 | src.biotech_pipeline.pipeline.etl_orchestrator | ERROR | ETL error for BIRAC/KIIT02236/BIG-23/23: Expecting value: line 1 column 1 (char 0)
Traceback (most recent call last):
  File "/Users/kaushalprajapati/Desktop/Development/BiD_Indian_BT_startups/.venv/lib/python3.12/site-packages/requests/models.py", line 976, in json
    return complexjson.loads(self.text, **kwargs)
           ^^^^^^^^^^^^^^^^^^^^^^^^^^^^^^^^^^^^^^
  File "/Users/kaushalprajapati/.local/share/uv/python/cpython-3.12.10-macos-aarch64-none/lib/python3.12/json/__init__.py", line 346, in loads
    return _default_decoder.decode(s)
           ^^^^^^^^^^^^^^^^^^^^^^^^^^
  File "/Users/kaushalprajapati/.local/share/uv/python/cpython-3.12.10-macos-aarch64-none/lib/python3.12/json/decoder.py", line 338, in decode
    obj, end = self.raw_decode(s, idx=_w(s, 0).end())
               ^^^^^^^^^^^^^^^^^^^^^^^^^^^^^^^^^^^^^^
  File "/Users/kaushalprajapati/.local/share/uv/python/cpython-3.12.10-macos-aarch64-none/lib/python3.12/json/decoder.py", line 356, in raw_decode
    raise JSONDecodeError("Expecting value", s, err.value) from None
json.decoder.JSONDecodeError: Expecting value: line 1 column 1 (char 0)

During handling of the above exception, another exception occurred:

Traceback (most recent call last):
  File "/Users/kaushalprajapati/Desktop/Development/BiD_Indian_BT_startups/src/biotech_pipeline/extractors/web_extractor.py", line 35, in extract_patents
    data = resp.json()  # assume JSON API
           ^^^^^^^^^^^
  File "/Users/kaushalprajapati/Desktop/Development/BiD_Indian_BT_startups/.venv/lib/python3.12/site-packages/requests/models.py", line 980, in json
    raise RequestsJSONDecodeError(e.msg, e.doc, e.pos)
requests.exceptions.JSONDecodeError: Expecting value: line 1 column 1 (char 0)

During handling of the above exception, another exception occurred:

Traceback (most recent call last):
  File "/Users/kaushalprajapati/Desktop/Development/BiD_Indian_BT_startups/src/biotech_pipeline/pipeline/etl_orchestrator.py", line 55, in run
    birac_data = self.birac_extractor.extract(name)
                 ^^^^^^^^^^^^^^^^^^^^^^^^^^^^^^^^^^
  File "/Users/kaushalprajapati/Desktop/Development/BiD_Indian_BT_startups/src/biotech_pipeline/extractors/web_extractor.py", line 103, in extract
    patents = self.extract_patents(company_name)
              ^^^^^^^^^^^^^^^^^^^^^^^^^^^^^^^^^^
  File "/Users/kaushalprajapati/Desktop/Development/BiD_Indian_BT_startups/src/biotech_pipeline/extractors/web_extractor.py", line 49, in extract_patents
    raise NetworkError(str(e), url)
src.biotech_pipeline.utils.exceptions.NetworkError: Expecting value: line 1 column 1 (char 0)
2025-08-11 11:02:48,923 | src.biotech_pipeline.pipeline.etl_orchestrator | ERROR | ETL error for BIRAC/SINE0709/BIG-23/23: Expecting value: line 1 column 1 (char 0)
Traceback (most recent call last):
  File "/Users/kaushalprajapati/Desktop/Development/BiD_Indian_BT_startups/.venv/lib/python3.12/site-packages/requests/models.py", line 976, in json
    return complexjson.loads(self.text, **kwargs)
           ^^^^^^^^^^^^^^^^^^^^^^^^^^^^^^^^^^^^^^
  File "/Users/kaushalprajapati/.local/share/uv/python/cpython-3.12.10-macos-aarch64-none/lib/python3.12/json/__init__.py", line 346, in loads
    return _default_decoder.decode(s)
           ^^^^^^^^^^^^^^^^^^^^^^^^^^
  File "/Users/kaushalprajapati/.local/share/uv/python/cpython-3.12.10-macos-aarch64-none/lib/python3.12/json/decoder.py", line 338, in decode
    obj, end = self.raw_decode(s, idx=_w(s, 0).end())
               ^^^^^^^^^^^^^^^^^^^^^^^^^^^^^^^^^^^^^^
  File "/Users/kaushalprajapati/.local/share/uv/python/cpython-3.12.10-macos-aarch64-none/lib/python3.12/json/decoder.py", line 356, in raw_decode
    raise JSONDecodeError("Expecting value", s, err.value) from None
json.decoder.JSONDecodeError: Expecting value: line 1 column 1 (char 0)

During handling of the above exception, another exception occurred:

Traceback (most recent call last):
  File "/Users/kaushalprajapati/Desktop/Development/BiD_Indian_BT_startups/src/biotech_pipeline/extractors/web_extractor.py", line 35, in extract_patents
    data = resp.json()  # assume JSON API
           ^^^^^^^^^^^
  File "/Users/kaushalprajapati/Desktop/Development/BiD_Indian_BT_startups/.venv/lib/python3.12/site-packages/requests/models.py", line 980, in json
    raise RequestsJSONDecodeError(e.msg, e.doc, e.pos)
requests.exceptions.JSONDecodeError: Expecting value: line 1 column 1 (char 0)

During handling of the above exception, another exception occurred:

Traceback (most recent call last):
  File "/Users/kaushalprajapati/Desktop/Development/BiD_Indian_BT_startups/src/biotech_pipeline/pipeline/etl_orchestrator.py", line 55, in run
    birac_data = self.birac_extractor.extract(name)
                 ^^^^^^^^^^^^^^^^^^^^^^^^^^^^^^^^^^
  File "/Users/kaushalprajapati/Desktop/Development/BiD_Indian_BT_startups/src/biotech_pipeline/extractors/web_extractor.py", line 103, in extract
    patents = self.extract_patents(company_name)
              ^^^^^^^^^^^^^^^^^^^^^^^^^^^^^^^^^^
  File "/Users/kaushalprajapati/Desktop/Development/BiD_Indian_BT_startups/src/biotech_pipeline/extractors/web_extractor.py", line 49, in extract_patents
    raise NetworkError(str(e), url)
src.biotech_pipeline.utils.exceptions.NetworkError: Expecting value: line 1 column 1 (char 0)
2025-08-11 11:03:19,844 | src.biotech_pipeline.pipeline.etl_orchestrator | ERROR | ETL error for BIRAC/SIIC0882/BIG-22/23: Expecting value: line 1 column 1 (char 0)
Traceback (most recent call last):
  File "/Users/kaushalprajapati/Desktop/Development/BiD_Indian_BT_startups/.venv/lib/python3.12/site-packages/requests/models.py", line 976, in json
    return complexjson.loads(self.text, **kwargs)
           ^^^^^^^^^^^^^^^^^^^^^^^^^^^^^^^^^^^^^^
  File "/Users/kaushalprajapati/.local/share/uv/python/cpython-3.12.10-macos-aarch64-none/lib/python3.12/json/__init__.py", line 346, in loads
    return _default_decoder.decode(s)
           ^^^^^^^^^^^^^^^^^^^^^^^^^^
  File "/Users/kaushalprajapati/.local/share/uv/python/cpython-3.12.10-macos-aarch64-none/lib/python3.12/json/decoder.py", line 338, in decode
    obj, end = self.raw_decode(s, idx=_w(s, 0).end())
               ^^^^^^^^^^^^^^^^^^^^^^^^^^^^^^^^^^^^^^
  File "/Users/kaushalprajapati/.local/share/uv/python/cpython-3.12.10-macos-aarch64-none/lib/python3.12/json/decoder.py", line 356, in raw_decode
    raise JSONDecodeError("Expecting value", s, err.value) from None
json.decoder.JSONDecodeError: Expecting value: line 1 column 1 (char 0)

During handling of the above exception, another exception occurred:

Traceback (most recent call last):
  File "/Users/kaushalprajapati/Desktop/Development/BiD_Indian_BT_startups/src/biotech_pipeline/extractors/web_extractor.py", line 35, in extract_patents
    data = resp.json()  # assume JSON API
           ^^^^^^^^^^^
  File "/Users/kaushalprajapati/Desktop/Development/BiD_Indian_BT_startups/.venv/lib/python3.12/site-packages/requests/models.py", line 980, in json
    raise RequestsJSONDecodeError(e.msg, e.doc, e.pos)
requests.exceptions.JSONDecodeError: Expecting value: line 1 column 1 (char 0)

During handling of the above exception, another exception occurred:

Traceback (most recent call last):
  File "/Users/kaushalprajapati/Desktop/Development/BiD_Indian_BT_startups/src/biotech_pipeline/pipeline/etl_orchestrator.py", line 55, in run
    birac_data = self.birac_extractor.extract(name)
                 ^^^^^^^^^^^^^^^^^^^^^^^^^^^^^^^^^^
  File "/Users/kaushalprajapati/Desktop/Development/BiD_Indian_BT_startups/src/biotech_pipeline/extractors/web_extractor.py", line 103, in extract
    patents = self.extract_patents(company_name)
              ^^^^^^^^^^^^^^^^^^^^^^^^^^^^^^^^^^
  File "/Users/kaushalprajapati/Desktop/Development/BiD_Indian_BT_startups/src/biotech_pipeline/extractors/web_extractor.py", line 49, in extract_patents
    raise NetworkError(str(e), url)
src.biotech_pipeline.utils.exceptions.NetworkError: Expecting value: line 1 column 1 (char 0)
2025-08-11 11:09:25,416 | src.biotech_pipeline.extractors.base_extractor | ERROR | Max retries exceeded for _fetch_serper: Serper API error
2025-08-11 11:09:25,417 | src.biotech_pipeline.extractors.news_scrapper | ERROR | NewsScraper.extract failed: _fetch_serper failed after 3 retries
Traceback (most recent call last):
  File "/Users/kaushalprajapati/Desktop/Development/BiD_Indian_BT_startups/src/biotech_pipeline/extractors/base_extractor.py", line 28, in wrapper
    return func(*args, **kwargs)
           ^^^^^^^^^^^^^^^^^^^^^
  File "/Users/kaushalprajapati/Desktop/Development/BiD_Indian_BT_startups/src/biotech_pipeline/extractors/news_scrapper.py", line 41, in _fetch_serper
    raise NetworkError("Serper API error", url, resp.status_code)
src.biotech_pipeline.utils.exceptions.NetworkError: Serper API error

During handling of the above exception, another exception occurred:

Traceback (most recent call last):
  File "/Users/kaushalprajapati/Desktop/Development/BiD_Indian_BT_startups/src/biotech_pipeline/extractors/news_scrapper.py", line 87, in extract
    return self._fetch_serper(query, limit)
           ^^^^^^^^^^^^^^^^^^^^^^^^^^^^^^^^
  File "/Users/kaushalprajapati/Desktop/Development/BiD_Indian_BT_startups/src/biotech_pipeline/extractors/base_extractor.py", line 33, in wrapper
    raise ExtractionError(
src.biotech_pipeline.utils.exceptions.ExtractionError: _fetch_serper failed after 3 retries
2025-08-11 11:09:25,421 | src.biotech_pipeline.agents.validation_agent | ERROR | Operation failed: src.biotech_pipeline.agents.validation_agent.validate_complete_profile (duration: 0.000s) - Error: 'Logger' object has no attribute 'log_validation'
2025-08-11 11:09:25,421 | src.biotech_pipeline.pipeline.etl_orchestrator | CRITICAL | Unexpected error for BIRAC/KIIT02236/BIG-23/23: 'Logger' object has no attribute 'log_validation'
Traceback (most recent call last):
  File "/Users/kaushalprajapati/Desktop/Development/BiD_Indian_BT_startups/src/biotech_pipeline/pipeline/etl_orchestrator.py", line 71, in run
    valid, report = validation_agent.validate_complete_profile(bid, payloads)
                    ^^^^^^^^^^^^^^^^^^^^^^^^^^^^^^^^^^^^^^^^^^^^^^^^^^^^^^^^^
  File "/Users/kaushalprajapati/Desktop/Development/BiD_Indian_BT_startups/src/biotech_pipeline/utils/logger.py", line 35, in wrapper
    result = func(*args, **kwargs)
             ^^^^^^^^^^^^^^^^^^^^^
  File "/Users/kaushalprajapati/Desktop/Development/BiD_Indian_BT_startups/src/biotech_pipeline/agents/validation_agent.py", line 63, in validate_complete_profile
    entity_results = self._validate_entity_list(entity_type, entity_data_list)
                     ^^^^^^^^^^^^^^^^^^^^^^^^^^^^^^^^^^^^^^^^^^^^^^^^^^^^^^^^^
  File "/Users/kaushalprajapati/Desktop/Development/BiD_Indian_BT_startups/src/biotech_pipeline/agents/validation_agent.py", line 115, in _validate_entity_list
    validation_results = self.validator.validate_entity(entity_type, entity_data)
                         ^^^^^^^^^^^^^^^^^^^^^^^^^^^^^^^^^^^^^^^^^^^^^^^^^^^^^^^^
  File "/Users/kaushalprajapati/Desktop/Development/BiD_Indian_BT_startups/src/biotech_pipeline/processors/validator.py", line 360, in validate_entity
    logger.log_validation(
    ^^^^^^^^^^^^^^^^^^^^^
AttributeError: 'Logger' object has no attribute 'log_validation'
2025-08-11 11:10:11,393 | src.biotech_pipeline.extractors.base_extractor | ERROR | Max retries exceeded for _fetch_serper: Serper API error
2025-08-11 11:10:11,394 | src.biotech_pipeline.extractors.news_scrapper | ERROR | NewsScraper.extract failed: _fetch_serper failed after 3 retries
Traceback (most recent call last):
  File "/Users/kaushalprajapati/Desktop/Development/BiD_Indian_BT_startups/src/biotech_pipeline/extractors/base_extractor.py", line 28, in wrapper
    return func(*args, **kwargs)
           ^^^^^^^^^^^^^^^^^^^^^
  File "/Users/kaushalprajapati/Desktop/Development/BiD_Indian_BT_startups/src/biotech_pipeline/extractors/news_scrapper.py", line 41, in _fetch_serper
    raise NetworkError("Serper API error", url, resp.status_code)
src.biotech_pipeline.utils.exceptions.NetworkError: Serper API error

During handling of the above exception, another exception occurred:

Traceback (most recent call last):
  File "/Users/kaushalprajapati/Desktop/Development/BiD_Indian_BT_startups/src/biotech_pipeline/extractors/news_scrapper.py", line 87, in extract
    return self._fetch_serper(query, limit)
           ^^^^^^^^^^^^^^^^^^^^^^^^^^^^^^^^
  File "/Users/kaushalprajapati/Desktop/Development/BiD_Indian_BT_startups/src/biotech_pipeline/extractors/base_extractor.py", line 33, in wrapper
    raise ExtractionError(
src.biotech_pipeline.utils.exceptions.ExtractionError: _fetch_serper failed after 3 retries
2025-08-11 11:10:11,396 | src.biotech_pipeline.pipeline.etl_orchestrator | CRITICAL | Unexpected error for BIRAC/SINE0709/BIG-23/23: 'tuple' object has no attribute 'strip'
Traceback (most recent call last):
  File "/Users/kaushalprajapati/Desktop/Development/BiD_Indian_BT_startups/src/biotech_pipeline/pipeline/etl_orchestrator.py", line 65, in run
    payloads = self.processor.prepare_payloads(
               ^^^^^^^^^^^^^^^^^^^^^^^^^^^^^^^^
  File "/Users/kaushalprajapati/Desktop/Development/BiD_Indian_BT_startups/src/biotech_pipeline/processors/data_processor.py", line 60, in prepare_payloads
    "website_url": clean_url(consolidated.get("website_url") or ""),
                   ^^^^^^^^^^^^^^^^^^^^^^^^^^^^^^^^^^^^^^^^^^^^^^^^
  File "/Users/kaushalprajapati/Desktop/Development/BiD_Indian_BT_startups/src/biotech_pipeline/processors/data_cleaner.py", line 22, in clean_url
    url = url.strip()
          ^^^^^^^^^
AttributeError: 'tuple' object has no attribute 'strip'
2025-08-11 11:11:18,931 | src.biotech_pipeline.extractors.base_extractor | ERROR | Max retries exceeded for _fetch_serper: Serper API error
2025-08-11 11:11:18,932 | src.biotech_pipeline.extractors.news_scrapper | ERROR | NewsScraper.extract failed: _fetch_serper failed after 3 retries
Traceback (most recent call last):
  File "/Users/kaushalprajapati/Desktop/Development/BiD_Indian_BT_startups/src/biotech_pipeline/extractors/base_extractor.py", line 28, in wrapper
    return func(*args, **kwargs)
           ^^^^^^^^^^^^^^^^^^^^^
  File "/Users/kaushalprajapati/Desktop/Development/BiD_Indian_BT_startups/src/biotech_pipeline/extractors/news_scrapper.py", line 41, in _fetch_serper
    raise NetworkError("Serper API error", url, resp.status_code)
src.biotech_pipeline.utils.exceptions.NetworkError: Serper API error

During handling of the above exception, another exception occurred:

Traceback (most recent call last):
  File "/Users/kaushalprajapati/Desktop/Development/BiD_Indian_BT_startups/src/biotech_pipeline/extractors/news_scrapper.py", line 87, in extract
    return self._fetch_serper(query, limit)
           ^^^^^^^^^^^^^^^^^^^^^^^^^^^^^^^^
  File "/Users/kaushalprajapati/Desktop/Development/BiD_Indian_BT_startups/src/biotech_pipeline/extractors/base_extractor.py", line 33, in wrapper
    raise ExtractionError(
src.biotech_pipeline.utils.exceptions.ExtractionError: _fetch_serper failed after 3 retries
2025-08-11 11:11:18,934 | src.biotech_pipeline.pipeline.etl_orchestrator | CRITICAL | Unexpected error for BIRAC/SIIC0882/BIG-22/23: 'tuple' object has no attribute 'strip'
Traceback (most recent call last):
  File "/Users/kaushalprajapati/Desktop/Development/BiD_Indian_BT_startups/src/biotech_pipeline/pipeline/etl_orchestrator.py", line 65, in run
    payloads = self.processor.prepare_payloads(
               ^^^^^^^^^^^^^^^^^^^^^^^^^^^^^^^^
  File "/Users/kaushalprajapati/Desktop/Development/BiD_Indian_BT_startups/src/biotech_pipeline/processors/data_processor.py", line 60, in prepare_payloads
    "website_url": clean_url(consolidated.get("website_url") or ""),
                   ^^^^^^^^^^^^^^^^^^^^^^^^^^^^^^^^^^^^^^^^^^^^^^^^
  File "/Users/kaushalprajapati/Desktop/Development/BiD_Indian_BT_startups/src/biotech_pipeline/processors/data_cleaner.py", line 22, in clean_url
    url = url.strip()
          ^^^^^^^^^
AttributeError: 'tuple' object has no attribute 'strip'
2025-08-11 11:12:19,777 | src.biotech_pipeline.extractors.website_scraper | ERROR | WebsiteExtractor network error: HTTPSConnectionPool(host='www.cancrie.com', port=443): Max retries exceeded with url: / (Caused by ConnectTimeoutError(<urllib3.connection.HTTPSConnection object at 0x129061310>, 'Connection to www.cancrie.com timed out. (connect timeout=10)'))
2025-08-11 11:12:37,929 | src.biotech_pipeline.extractors.base_extractor | ERROR | Max retries exceeded for _fetch_serper: Serper API error
2025-08-11 11:12:37,930 | src.biotech_pipeline.extractors.news_scrapper | ERROR | NewsScraper.extract failed: _fetch_serper failed after 3 retries
Traceback (most recent call last):
  File "/Users/kaushalprajapati/Desktop/Development/BiD_Indian_BT_startups/src/biotech_pipeline/extractors/base_extractor.py", line 28, in wrapper
    return func(*args, **kwargs)
           ^^^^^^^^^^^^^^^^^^^^^
  File "/Users/kaushalprajapati/Desktop/Development/BiD_Indian_BT_startups/src/biotech_pipeline/extractors/news_scrapper.py", line 41, in _fetch_serper
    raise NetworkError("Serper API error", url, resp.status_code)
src.biotech_pipeline.utils.exceptions.NetworkError: Serper API error

During handling of the above exception, another exception occurred:

Traceback (most recent call last):
  File "/Users/kaushalprajapati/Desktop/Development/BiD_Indian_BT_startups/src/biotech_pipeline/extractors/news_scrapper.py", line 87, in extract
    return self._fetch_serper(query, limit)
           ^^^^^^^^^^^^^^^^^^^^^^^^^^^^^^^^
  File "/Users/kaushalprajapati/Desktop/Development/BiD_Indian_BT_startups/src/biotech_pipeline/extractors/base_extractor.py", line 33, in wrapper
    raise ExtractionError(
src.biotech_pipeline.utils.exceptions.ExtractionError: _fetch_serper failed after 3 retries
2025-08-11 11:12:37,931 | src.biotech_pipeline.pipeline.etl_orchestrator | CRITICAL | Unexpected error for BIRAC/IKP01696/BIG-22/23: 'tuple' object has no attribute 'strip'
Traceback (most recent call last):
  File "/Users/kaushalprajapati/Desktop/Development/BiD_Indian_BT_startups/src/biotech_pipeline/pipeline/etl_orchestrator.py", line 65, in run
    payloads = self.processor.prepare_payloads(
               ^^^^^^^^^^^^^^^^^^^^^^^^^^^^^^^^
  File "/Users/kaushalprajapati/Desktop/Development/BiD_Indian_BT_startups/src/biotech_pipeline/processors/data_processor.py", line 60, in prepare_payloads
    "website_url": clean_url(consolidated.get("website_url") or ""),
                   ^^^^^^^^^^^^^^^^^^^^^^^^^^^^^^^^^^^^^^^^^^^^^^^^
  File "/Users/kaushalprajapati/Desktop/Development/BiD_Indian_BT_startups/src/biotech_pipeline/processors/data_cleaner.py", line 22, in clean_url
    url = url.strip()
          ^^^^^^^^^
AttributeError: 'tuple' object has no attribute 'strip'
2025-08-11 11:13:45,216 | src.biotech_pipeline.extractors.base_extractor | ERROR | Max retries exceeded for _fetch_serper: Serper API error
2025-08-11 11:13:45,218 | src.biotech_pipeline.extractors.news_scrapper | ERROR | NewsScraper.extract failed: _fetch_serper failed after 3 retries
Traceback (most recent call last):
  File "/Users/kaushalprajapati/Desktop/Development/BiD_Indian_BT_startups/src/biotech_pipeline/extractors/base_extractor.py", line 28, in wrapper
    return func(*args, **kwargs)
           ^^^^^^^^^^^^^^^^^^^^^
  File "/Users/kaushalprajapati/Desktop/Development/BiD_Indian_BT_startups/src/biotech_pipeline/extractors/news_scrapper.py", line 41, in _fetch_serper
    raise NetworkError("Serper API error", url, resp.status_code)
src.biotech_pipeline.utils.exceptions.NetworkError: Serper API error

During handling of the above exception, another exception occurred:

Traceback (most recent call last):
  File "/Users/kaushalprajapati/Desktop/Development/BiD_Indian_BT_startups/src/biotech_pipeline/extractors/news_scrapper.py", line 87, in extract
    return self._fetch_serper(query, limit)
           ^^^^^^^^^^^^^^^^^^^^^^^^^^^^^^^^
  File "/Users/kaushalprajapati/Desktop/Development/BiD_Indian_BT_startups/src/biotech_pipeline/extractors/base_extractor.py", line 33, in wrapper
    raise ExtractionError(
src.biotech_pipeline.utils.exceptions.ExtractionError: _fetch_serper failed after 3 retries
2025-08-11 11:13:45,219 | src.biotech_pipeline.pipeline.etl_orchestrator | CRITICAL | Unexpected error for BIRAC/IKP01613/BIG-21/22: 'tuple' object has no attribute 'strip'
Traceback (most recent call last):
  File "/Users/kaushalprajapati/Desktop/Development/BiD_Indian_BT_startups/src/biotech_pipeline/pipeline/etl_orchestrator.py", line 65, in run
    payloads = self.processor.prepare_payloads(
               ^^^^^^^^^^^^^^^^^^^^^^^^^^^^^^^^
  File "/Users/kaushalprajapati/Desktop/Development/BiD_Indian_BT_startups/src/biotech_pipeline/processors/data_processor.py", line 60, in prepare_payloads
    "website_url": clean_url(consolidated.get("website_url") or ""),
                   ^^^^^^^^^^^^^^^^^^^^^^^^^^^^^^^^^^^^^^^^^^^^^^^^
  File "/Users/kaushalprajapati/Desktop/Development/BiD_Indian_BT_startups/src/biotech_pipeline/processors/data_cleaner.py", line 22, in clean_url
    url = url.strip()
          ^^^^^^^^^
AttributeError: 'tuple' object has no attribute 'strip'
2025-08-11 11:24:40,468 | src.biotech_pipeline.extractors.base_extractor | ERROR | Max retries exceeded for _fetch_serper: Serper API error
2025-08-11 11:24:41,289 | src.biotech_pipeline.agents.validation_agent | ERROR | Operation failed: src.biotech_pipeline.agents.validation_agent.validate_complete_profile (duration: 0.000s) - Error: 'Logger' object has no attribute 'log_validation'
2025-08-11 11:24:41,289 | src.biotech_pipeline.pipeline.etl_orchestrator | CRITICAL | Unexpected error for BIRAC/KIIT02236/BIG-23/23: 'Logger' object has no attribute 'log_validation'
Traceback (most recent call last):
  File "/Users/kaushalprajapati/Desktop/Development/BiD_Indian_BT_startups/src/biotech_pipeline/pipeline/etl_orchestrator.py", line 71, in run
    valid, report = validation_agent.validate_complete_profile(bid, payloads)
                    ^^^^^^^^^^^^^^^^^^^^^^^^^^^^^^^^^^^^^^^^^^^^^^^^^^^^^^^^^
  File "/Users/kaushalprajapati/Desktop/Development/BiD_Indian_BT_startups/src/biotech_pipeline/utils/logger.py", line 35, in wrapper
    result = func(*args, **kwargs)
             ^^^^^^^^^^^^^^^^^^^^^
  File "/Users/kaushalprajapati/Desktop/Development/BiD_Indian_BT_startups/src/biotech_pipeline/agents/validation_agent.py", line 63, in validate_complete_profile
    entity_results = self._validate_entity_list(entity_type, entity_data_list)
                     ^^^^^^^^^^^^^^^^^^^^^^^^^^^^^^^^^^^^^^^^^^^^^^^^^^^^^^^^^
  File "/Users/kaushalprajapati/Desktop/Development/BiD_Indian_BT_startups/src/biotech_pipeline/agents/validation_agent.py", line 115, in _validate_entity_list
    validation_results = self.validator.validate_entity(entity_type, entity_data)
                         ^^^^^^^^^^^^^^^^^^^^^^^^^^^^^^^^^^^^^^^^^^^^^^^^^^^^^^^^
  File "/Users/kaushalprajapati/Desktop/Development/BiD_Indian_BT_startups/src/biotech_pipeline/processors/validator.py", line 360, in validate_entity
    logger.log_validation(
    ^^^^^^^^^^^^^^^^^^^^^
AttributeError: 'Logger' object has no attribute 'log_validation'
2025-08-11 11:28:57,031 | src.biotech_pipeline.extractors.base_extractor | ERROR | Max retries exceeded for _fetch_serper: Serper API error
2025-08-11 11:28:57,809 | src.biotech_pipeline.agents.validation_agent | ERROR | Operation failed: src.biotech_pipeline.agents.validation_agent.validate_complete_profile (duration: 0.001s) - Error: ValidationError.__init__() missing 2 required positional arguments: 'field' and 'value'
Traceback (most recent call last):
  File "/Users/kaushalprajapati/Desktop/Development/BiD_Indian_BT_startups/src/biotech_pipeline/utils/logger.py", line 74, in wrapper
    result = func(*args, **kwargs)
             ^^^^^^^^^^^^^^^^^^^^^
  File "/Users/kaushalprajapati/Desktop/Development/BiD_Indian_BT_startups/src/biotech_pipeline/agents/validation_agent.py", line 63, in validate_complete_profile
    entity_results = self._validate_entity_list(entity_type, entity_data_list)
                     ^^^^^^^^^^^^^^^^^^^^^^^^^^^^^^^^^^^^^^^^^^^^^^^^^^^^^^^^^
  File "/Users/kaushalprajapati/Desktop/Development/BiD_Indian_BT_startups/src/biotech_pipeline/agents/validation_agent.py", line 115, in _validate_entity_list
    validation_results = self.validator.validate_entity(entity_type, entity_data)
                         ^^^^^^^^^^^^^^^^^^^^^^^^^^^^^^^^^^^^^^^^^^^^^^^^^^^^^^^^
  File "/Users/kaushalprajapati/Desktop/Development/BiD_Indian_BT_startups/src/biotech_pipeline/processors/validator.py", line 346, in validate_entity
    raise ValidationError(f"Unknown entity type: {entity_type}")
          ^^^^^^^^^^^^^^^^^^^^^^^^^^^^^^^^^^^^^^^^^^^^^^^^^^^^^^
TypeError: ValidationError.__init__() missing 2 required positional arguments: 'field' and 'value'
2025-08-11 11:28:57,812 | src.biotech_pipeline.pipeline.etl_orchestrator | CRITICAL | Unexpected error for BIRAC/KIIT02236/BIG-23/23: ValidationError.__init__() missing 2 required positional arguments: 'field' and 'value'
Traceback (most recent call last):
  File "/Users/kaushalprajapati/Desktop/Development/BiD_Indian_BT_startups/src/biotech_pipeline/pipeline/etl_orchestrator.py", line 71, in run
    valid, report = validation_agent.validate_complete_profile(bid, payloads)
                    ^^^^^^^^^^^^^^^^^^^^^^^^^^^^^^^^^^^^^^^^^^^^^^^^^^^^^^^^^
  File "/Users/kaushalprajapati/Desktop/Development/BiD_Indian_BT_startups/src/biotech_pipeline/utils/logger.py", line 74, in wrapper
    result = func(*args, **kwargs)
             ^^^^^^^^^^^^^^^^^^^^^
  File "/Users/kaushalprajapati/Desktop/Development/BiD_Indian_BT_startups/src/biotech_pipeline/agents/validation_agent.py", line 63, in validate_complete_profile
    entity_results = self._validate_entity_list(entity_type, entity_data_list)
                     ^^^^^^^^^^^^^^^^^^^^^^^^^^^^^^^^^^^^^^^^^^^^^^^^^^^^^^^^^
  File "/Users/kaushalprajapati/Desktop/Development/BiD_Indian_BT_startups/src/biotech_pipeline/agents/validation_agent.py", line 115, in _validate_entity_list
    validation_results = self.validator.validate_entity(entity_type, entity_data)
                         ^^^^^^^^^^^^^^^^^^^^^^^^^^^^^^^^^^^^^^^^^^^^^^^^^^^^^^^^
  File "/Users/kaushalprajapati/Desktop/Development/BiD_Indian_BT_startups/src/biotech_pipeline/processors/validator.py", line 346, in validate_entity
    raise ValidationError(f"Unknown entity type: {entity_type}")
          ^^^^^^^^^^^^^^^^^^^^^^^^^^^^^^^^^^^^^^^^^^^^^^^^^^^^^^
TypeError: ValidationError.__init__() missing 2 required positional arguments: 'field' and 'value'
2025-08-11 11:29:59,576 | src.biotech_pipeline.extractors.base_extractor | ERROR | Max retries exceeded for _fetch_serper: Serper API error
2025-08-11 11:30:00,295 | src.biotech_pipeline.pipeline.etl_orchestrator | CRITICAL | Unexpected error for BIRAC/SINE0709/BIG-23/23: 'tuple' object has no attribute 'strip'
Traceback (most recent call last):
  File "/Users/kaushalprajapati/Desktop/Development/BiD_Indian_BT_startups/src/biotech_pipeline/pipeline/etl_orchestrator.py", line 65, in run
    payloads = self.processor.prepare_payloads(
               ^^^^^^^^^^^^^^^^^^^^^^^^^^^^^^^^
  File "/Users/kaushalprajapati/Desktop/Development/BiD_Indian_BT_startups/src/biotech_pipeline/processors/data_processor.py", line 61, in prepare_payloads
    "cin": validate_cin(consolidated.get("cin") or ""),
           ^^^^^^^^^^^^^^^^^^^^^^^^^^^^^^^^^^^^^^^^^^^
  File "/Users/kaushalprajapati/Desktop/Development/BiD_Indian_BT_startups/src/biotech_pipeline/processors/data_cleaner.py", line 92, in validate_cin
    cin = cin.strip().upper()
          ^^^^^^^^^
AttributeError: 'tuple' object has no attribute 'strip'
2025-08-11 11:31:04,628 | src.biotech_pipeline.extractors.base_extractor | ERROR | Max retries exceeded for _fetch_serper: Serper API error
2025-08-11 11:31:05,274 | src.biotech_pipeline.pipeline.etl_orchestrator | CRITICAL | Unexpected error for BIRAC/SIIC0882/BIG-22/23: 'tuple' object has no attribute 'strip'
Traceback (most recent call last):
  File "/Users/kaushalprajapati/Desktop/Development/BiD_Indian_BT_startups/src/biotech_pipeline/pipeline/etl_orchestrator.py", line 65, in run
    payloads = self.processor.prepare_payloads(
               ^^^^^^^^^^^^^^^^^^^^^^^^^^^^^^^^
  File "/Users/kaushalprajapati/Desktop/Development/BiD_Indian_BT_startups/src/biotech_pipeline/processors/data_processor.py", line 61, in prepare_payloads
    "cin": validate_cin(consolidated.get("cin") or ""),
           ^^^^^^^^^^^^^^^^^^^^^^^^^^^^^^^^^^^^^^^^^^^
  File "/Users/kaushalprajapati/Desktop/Development/BiD_Indian_BT_startups/src/biotech_pipeline/processors/data_cleaner.py", line 92, in validate_cin
    cin = cin.strip().upper()
          ^^^^^^^^^
AttributeError: 'tuple' object has no attribute 'strip'
2025-08-11 11:32:09,564 | src.biotech_pipeline.extractors.website_scraper | ERROR | WebsiteExtractor network error: HTTPSConnectionPool(host='www.cancrie.com', port=443): Max retries exceeded with url: / (Caused by ConnectTimeoutError(<urllib3.connection.HTTPSConnection object at 0x11c3b8fb0>, 'Connection to www.cancrie.com timed out. (connect timeout=10)'))
2025-08-11 11:32:27,826 | src.biotech_pipeline.extractors.base_extractor | ERROR | Max retries exceeded for _fetch_serper: Serper API error
2025-08-11 11:32:28,650 | src.biotech_pipeline.pipeline.etl_orchestrator | CRITICAL | Unexpected error for BIRAC/IKP01696/BIG-22/23: 'tuple' object has no attribute 'strip'
Traceback (most recent call last):
  File "/Users/kaushalprajapati/Desktop/Development/BiD_Indian_BT_startups/src/biotech_pipeline/pipeline/etl_orchestrator.py", line 65, in run
    payloads = self.processor.prepare_payloads(
               ^^^^^^^^^^^^^^^^^^^^^^^^^^^^^^^^
  File "/Users/kaushalprajapati/Desktop/Development/BiD_Indian_BT_startups/src/biotech_pipeline/processors/data_processor.py", line 61, in prepare_payloads
    "cin": validate_cin(consolidated.get("cin") or ""),
           ^^^^^^^^^^^^^^^^^^^^^^^^^^^^^^^^^^^^^^^^^^^
  File "/Users/kaushalprajapati/Desktop/Development/BiD_Indian_BT_startups/src/biotech_pipeline/processors/data_cleaner.py", line 92, in validate_cin
    cin = cin.strip().upper()
          ^^^^^^^^^
AttributeError: 'tuple' object has no attribute 'strip'
2025-08-11 11:34:39,513 | src.biotech_pipeline.extractors.base_extractor | ERROR | Max retries exceeded for _fetch_serper: Serper API error
2025-08-11 11:34:40,577 | src.biotech_pipeline.pipeline.etl_orchestrator | CRITICAL | Unexpected error for BIRAC/IKP01613/BIG-21/22: 'tuple' object has no attribute 'strip'
Traceback (most recent call last):
  File "/Users/kaushalprajapati/Desktop/Development/BiD_Indian_BT_startups/src/biotech_pipeline/pipeline/etl_orchestrator.py", line 65, in run
    payloads = self.processor.prepare_payloads(
               ^^^^^^^^^^^^^^^^^^^^^^^^^^^^^^^^
  File "/Users/kaushalprajapati/Desktop/Development/BiD_Indian_BT_startups/src/biotech_pipeline/processors/data_processor.py", line 61, in prepare_payloads
    "cin": validate_cin(consolidated.get("cin") or ""),
           ^^^^^^^^^^^^^^^^^^^^^^^^^^^^^^^^^^^^^^^^^^^
  File "/Users/kaushalprajapati/Desktop/Development/BiD_Indian_BT_startups/src/biotech_pipeline/processors/data_cleaner.py", line 92, in validate_cin
    cin = cin.strip().upper()
          ^^^^^^^^^
AttributeError: 'tuple' object has no attribute 'strip'
2025-08-11 11:35:44,526 | src.biotech_pipeline.extractors.base_extractor | ERROR | Max retries exceeded for _fetch_serper: Serper API error
2025-08-11 11:35:45,272 | src.biotech_pipeline.pipeline.etl_orchestrator | CRITICAL | Unexpected error for BIRAC/CCAMP01917/BIG-21/22: 'tuple' object has no attribute 'strip'
Traceback (most recent call last):
  File "/Users/kaushalprajapati/Desktop/Development/BiD_Indian_BT_startups/src/biotech_pipeline/pipeline/etl_orchestrator.py", line 65, in run
    payloads = self.processor.prepare_payloads(
               ^^^^^^^^^^^^^^^^^^^^^^^^^^^^^^^^
  File "/Users/kaushalprajapati/Desktop/Development/BiD_Indian_BT_startups/src/biotech_pipeline/processors/data_processor.py", line 61, in prepare_payloads
    "cin": validate_cin(consolidated.get("cin") or ""),
           ^^^^^^^^^^^^^^^^^^^^^^^^^^^^^^^^^^^^^^^^^^^
  File "/Users/kaushalprajapati/Desktop/Development/BiD_Indian_BT_startups/src/biotech_pipeline/processors/data_cleaner.py", line 92, in validate_cin
    cin = cin.strip().upper()
          ^^^^^^^^^
AttributeError: 'tuple' object has no attribute 'strip'
2025-08-11 11:37:01,961 | src.biotech_pipeline.extractors.base_extractor | ERROR | Max retries exceeded for _fetch_serper: Serper API error
2025-08-11 11:37:02,825 | src.biotech_pipeline.pipeline.etl_orchestrator | CRITICAL | Unexpected error for BIRAC/KIIT01604/BIG-20/22: 'tuple' object has no attribute 'strip'
Traceback (most recent call last):
  File "/Users/kaushalprajapati/Desktop/Development/BiD_Indian_BT_startups/src/biotech_pipeline/pipeline/etl_orchestrator.py", line 65, in run
    payloads = self.processor.prepare_payloads(
               ^^^^^^^^^^^^^^^^^^^^^^^^^^^^^^^^
  File "/Users/kaushalprajapati/Desktop/Development/BiD_Indian_BT_startups/src/biotech_pipeline/processors/data_processor.py", line 61, in prepare_payloads
    "cin": validate_cin(consolidated.get("cin") or ""),
           ^^^^^^^^^^^^^^^^^^^^^^^^^^^^^^^^^^^^^^^^^^^
  File "/Users/kaushalprajapati/Desktop/Development/BiD_Indian_BT_startups/src/biotech_pipeline/processors/data_cleaner.py", line 92, in validate_cin
    cin = cin.strip().upper()
          ^^^^^^^^^
AttributeError: 'tuple' object has no attribute 'strip'
2025-08-11 11:37:48,773 | src.biotech_pipeline.extractors.website_scraper | ERROR | WebsiteExtractor network error: HTTPSConnectionPool(host='www.innodxsolutions.com', port=443): Max retries exceeded with url: / (Caused by NameResolutionError("<urllib3.connection.HTTPSConnection object at 0x11f1f72c0>: Failed to resolve 'www.innodxsolutions.com' ([Errno 8] nodename nor servname provided, or not known)"))
2025-08-11 11:38:07,216 | src.biotech_pipeline.extractors.base_extractor | ERROR | Max retries exceeded for _fetch_serper: Serper API error
2025-08-11 11:38:08,113 | src.biotech_pipeline.pipeline.etl_orchestrator | CRITICAL | Unexpected error for BIRAC/VENTURE0864/BIG-20/22: 'tuple' object has no attribute 'strip'
Traceback (most recent call last):
  File "/Users/kaushalprajapati/Desktop/Development/BiD_Indian_BT_startups/src/biotech_pipeline/pipeline/etl_orchestrator.py", line 65, in run
    payloads = self.processor.prepare_payloads(
               ^^^^^^^^^^^^^^^^^^^^^^^^^^^^^^^^
  File "/Users/kaushalprajapati/Desktop/Development/BiD_Indian_BT_startups/src/biotech_pipeline/processors/data_processor.py", line 61, in prepare_payloads
    "cin": validate_cin(consolidated.get("cin") or ""),
           ^^^^^^^^^^^^^^^^^^^^^^^^^^^^^^^^^^^^^^^^^^^
  File "/Users/kaushalprajapati/Desktop/Development/BiD_Indian_BT_startups/src/biotech_pipeline/processors/data_cleaner.py", line 92, in validate_cin
    cin = cin.strip().upper()
          ^^^^^^^^^
AttributeError: 'tuple' object has no attribute 'strip'
2025-08-11 11:38:59,314 | src.biotech_pipeline.extractors.base_extractor | ERROR | Max retries exceeded for _fetch_serper: Serper API error
2025-08-11 11:38:59,964 | src.biotech_pipeline.pipeline.etl_orchestrator | CRITICAL | Unexpected error for BIRAC/CCAMP01675/BIG-19/21: 'tuple' object has no attribute 'strip'
Traceback (most recent call last):
  File "/Users/kaushalprajapati/Desktop/Development/BiD_Indian_BT_startups/src/biotech_pipeline/pipeline/etl_orchestrator.py", line 65, in run
    payloads = self.processor.prepare_payloads(
               ^^^^^^^^^^^^^^^^^^^^^^^^^^^^^^^^
  File "/Users/kaushalprajapati/Desktop/Development/BiD_Indian_BT_startups/src/biotech_pipeline/processors/data_processor.py", line 61, in prepare_payloads
    "cin": validate_cin(consolidated.get("cin") or ""),
           ^^^^^^^^^^^^^^^^^^^^^^^^^^^^^^^^^^^^^^^^^^^
  File "/Users/kaushalprajapati/Desktop/Development/BiD_Indian_BT_startups/src/biotech_pipeline/processors/data_cleaner.py", line 92, in validate_cin
    cin = cin.strip().upper()
          ^^^^^^^^^
AttributeError: 'tuple' object has no attribute 'strip'
2025-08-11 11:39:56,797 | src.biotech_pipeline.extractors.base_extractor | ERROR | Max retries exceeded for _fetch_serper: Serper API error
2025-08-11 11:39:57,462 | src.biotech_pipeline.pipeline.etl_orchestrator | CRITICAL | Unexpected error for BIRAC/CCAMP01624/BIG-19/21: 'tuple' object has no attribute 'strip'
Traceback (most recent call last):
  File "/Users/kaushalprajapati/Desktop/Development/BiD_Indian_BT_startups/src/biotech_pipeline/pipeline/etl_orchestrator.py", line 65, in run
    payloads = self.processor.prepare_payloads(
               ^^^^^^^^^^^^^^^^^^^^^^^^^^^^^^^^
  File "/Users/kaushalprajapati/Desktop/Development/BiD_Indian_BT_startups/src/biotech_pipeline/processors/data_processor.py", line 61, in prepare_payloads
    "cin": validate_cin(consolidated.get("cin") or ""),
           ^^^^^^^^^^^^^^^^^^^^^^^^^^^^^^^^^^^^^^^^^^^
  File "/Users/kaushalprajapati/Desktop/Development/BiD_Indian_BT_startups/src/biotech_pipeline/processors/data_cleaner.py", line 92, in validate_cin
    cin = cin.strip().upper()
          ^^^^^^^^^
AttributeError: 'tuple' object has no attribute 'strip'
2025-08-11 11:45:05,500 | src.biotech_pipeline.extractors.base_extractor | ERROR | Max retries exceeded for _fetch_serper: Serper API error
2025-08-11 11:45:06,426 | src.biotech_pipeline.agents.validation_agent | ERROR | Operation failed: src.biotech_pipeline.agents.validation_agent.validate_complete_profile (duration: 0.001s) - Error: Unknown entity type: news_coverage
Traceback (most recent call last):
  File "/Users/kaushalprajapati/Desktop/Development/BiD_Indian_BT_startups/src/biotech_pipeline/utils/logger.py", line 59, in wrapper
    result = func(*args, **kwargs)
             ^^^^^^^^^^^^^^^^^^^^^
  File "/Users/kaushalprajapati/Desktop/Development/BiD_Indian_BT_startups/src/biotech_pipeline/agents/validation_agent.py", line 63, in validate_complete_profile
    entity_results = self._validate_entity_list(entity_type, entity_data_list)
                     ^^^^^^^^^^^^^^^^^^^^^^^^^^^^^^^^^^^^^^^^^^^^^^^^^^^^^^^^^
  File "/Users/kaushalprajapati/Desktop/Development/BiD_Indian_BT_startups/src/biotech_pipeline/agents/validation_agent.py", line 115, in _validate_entity_list
    validation_results = self.validator.validate_entity(entity_type, entity_data)
                         ^^^^^^^^^^^^^^^^^^^^^^^^^^^^^^^^^^^^^^^^^^^^^^^^^^^^^^^^
  File "/Users/kaushalprajapati/Desktop/Development/BiD_Indian_BT_startups/src/biotech_pipeline/processors/validator.py", line 312, in validate_entity
    raise ValidationError(
src.biotech_pipeline.utils.exceptions.ValidationError: Unknown entity type: news_coverage
2025-08-11 11:45:06,429 | src.biotech_pipeline.pipeline.etl_orchestrator | ERROR | Validation agent crashed for BIRAC/KIIT02236/BIG-23/23: Unknown entity type: news_coverage
Traceback (most recent call last):
  File "/Users/kaushalprajapati/Desktop/Development/BiD_Indian_BT_startups/src/biotech_pipeline/pipeline/etl_orchestrator.py", line 72, in run
    valid, report = validation_agent.validate_complete_profile(bid, payloads)
                    ^^^^^^^^^^^^^^^^^^^^^^^^^^^^^^^^^^^^^^^^^^^^^^^^^^^^^^^^^
  File "/Users/kaushalprajapati/Desktop/Development/BiD_Indian_BT_startups/src/biotech_pipeline/utils/logger.py", line 59, in wrapper
    result = func(*args, **kwargs)
             ^^^^^^^^^^^^^^^^^^^^^
  File "/Users/kaushalprajapati/Desktop/Development/BiD_Indian_BT_startups/src/biotech_pipeline/agents/validation_agent.py", line 63, in validate_complete_profile
    entity_results = self._validate_entity_list(entity_type, entity_data_list)
                     ^^^^^^^^^^^^^^^^^^^^^^^^^^^^^^^^^^^^^^^^^^^^^^^^^^^^^^^^^
  File "/Users/kaushalprajapati/Desktop/Development/BiD_Indian_BT_startups/src/biotech_pipeline/agents/validation_agent.py", line 115, in _validate_entity_list
    validation_results = self.validator.validate_entity(entity_type, entity_data)
                         ^^^^^^^^^^^^^^^^^^^^^^^^^^^^^^^^^^^^^^^^^^^^^^^^^^^^^^^^
  File "/Users/kaushalprajapati/Desktop/Development/BiD_Indian_BT_startups/src/biotech_pipeline/processors/validator.py", line 312, in validate_entity
    raise ValidationError(
src.biotech_pipeline.utils.exceptions.ValidationError: Unknown entity type: news_coverage
2025-08-11 11:45:51,170 | src.biotech_pipeline.extractors.base_extractor | ERROR | Max retries exceeded for _fetch_serper: Serper API error
2025-08-11 11:45:51,987 | src.biotech_pipeline.pipeline.etl_orchestrator | CRITICAL | Unexpected error for BIRAC/SINE0709/BIG-23/23: 'tuple' object has no attribute 'strip'
Traceback (most recent call last):
  File "/Users/kaushalprajapati/Desktop/Development/BiD_Indian_BT_startups/src/biotech_pipeline/pipeline/etl_orchestrator.py", line 65, in run
    payloads = self.processor.prepare_payloads(
               ^^^^^^^^^^^^^^^^^^^^^^^^^^^^^^^^
  File "/Users/kaushalprajapati/Desktop/Development/BiD_Indian_BT_startups/src/biotech_pipeline/processors/data_processor.py", line 61, in prepare_payloads
    "cin": validate_cin(consolidated.get("cin") or ""),
           ^^^^^^^^^^^^^^^^^^^^^^^^^^^^^^^^^^^^^^^^^^^
  File "/Users/kaushalprajapati/Desktop/Development/BiD_Indian_BT_startups/src/biotech_pipeline/processors/data_cleaner.py", line 92, in validate_cin
    cin = cin.strip().upper()
          ^^^^^^^^^
AttributeError: 'tuple' object has no attribute 'strip'
2025-08-11 11:46:42,346 | src.biotech_pipeline.extractors.base_extractor | ERROR | Max retries exceeded for _fetch_serper: Serper API error
2025-08-11 11:46:42,993 | src.biotech_pipeline.pipeline.etl_orchestrator | CRITICAL | Unexpected error for BIRAC/SIIC0882/BIG-22/23: 'tuple' object has no attribute 'strip'
Traceback (most recent call last):
  File "/Users/kaushalprajapati/Desktop/Development/BiD_Indian_BT_startups/src/biotech_pipeline/pipeline/etl_orchestrator.py", line 65, in run
    payloads = self.processor.prepare_payloads(
               ^^^^^^^^^^^^^^^^^^^^^^^^^^^^^^^^
  File "/Users/kaushalprajapati/Desktop/Development/BiD_Indian_BT_startups/src/biotech_pipeline/processors/data_processor.py", line 61, in prepare_payloads
    "cin": validate_cin(consolidated.get("cin") or ""),
           ^^^^^^^^^^^^^^^^^^^^^^^^^^^^^^^^^^^^^^^^^^^
  File "/Users/kaushalprajapati/Desktop/Development/BiD_Indian_BT_startups/src/biotech_pipeline/processors/data_cleaner.py", line 92, in validate_cin
    cin = cin.strip().upper()
          ^^^^^^^^^
AttributeError: 'tuple' object has no attribute 'strip'
2025-08-11 11:47:35,263 | src.biotech_pipeline.extractors.website_scraper | ERROR | WebsiteExtractor network error: HTTPSConnectionPool(host='www.cancrie.com', port=443): Max retries exceeded with url: / (Caused by ConnectTimeoutError(<urllib3.connection.HTTPSConnection object at 0x11e6b5d00>, 'Connection to www.cancrie.com timed out. (connect timeout=10)'))
2025-08-11 11:47:55,744 | src.biotech_pipeline.extractors.base_extractor | ERROR | Max retries exceeded for _fetch_serper: Serper API error
2025-08-11 11:47:56,655 | src.biotech_pipeline.pipeline.etl_orchestrator | CRITICAL | Unexpected error for BIRAC/IKP01696/BIG-22/23: 'tuple' object has no attribute 'strip'
Traceback (most recent call last):
  File "/Users/kaushalprajapati/Desktop/Development/BiD_Indian_BT_startups/src/biotech_pipeline/pipeline/etl_orchestrator.py", line 65, in run
    payloads = self.processor.prepare_payloads(
               ^^^^^^^^^^^^^^^^^^^^^^^^^^^^^^^^
  File "/Users/kaushalprajapati/Desktop/Development/BiD_Indian_BT_startups/src/biotech_pipeline/processors/data_processor.py", line 61, in prepare_payloads
    "cin": validate_cin(consolidated.get("cin") or ""),
           ^^^^^^^^^^^^^^^^^^^^^^^^^^^^^^^^^^^^^^^^^^^
  File "/Users/kaushalprajapati/Desktop/Development/BiD_Indian_BT_startups/src/biotech_pipeline/processors/data_cleaner.py", line 92, in validate_cin
    cin = cin.strip().upper()
          ^^^^^^^^^
AttributeError: 'tuple' object has no attribute 'strip'
2025-08-11 11:48:51,589 | src.biotech_pipeline.extractors.base_extractor | ERROR | Max retries exceeded for _fetch_serper: Serper API error
2025-08-11 11:48:52,433 | src.biotech_pipeline.pipeline.etl_orchestrator | CRITICAL | Unexpected error for BIRAC/IKP01613/BIG-21/22: 'tuple' object has no attribute 'strip'
Traceback (most recent call last):
  File "/Users/kaushalprajapati/Desktop/Development/BiD_Indian_BT_startups/src/biotech_pipeline/pipeline/etl_orchestrator.py", line 65, in run
    payloads = self.processor.prepare_payloads(
               ^^^^^^^^^^^^^^^^^^^^^^^^^^^^^^^^
  File "/Users/kaushalprajapati/Desktop/Development/BiD_Indian_BT_startups/src/biotech_pipeline/processors/data_processor.py", line 61, in prepare_payloads
    "cin": validate_cin(consolidated.get("cin") or ""),
           ^^^^^^^^^^^^^^^^^^^^^^^^^^^^^^^^^^^^^^^^^^^
  File "/Users/kaushalprajapati/Desktop/Development/BiD_Indian_BT_startups/src/biotech_pipeline/processors/data_cleaner.py", line 92, in validate_cin
    cin = cin.strip().upper()
          ^^^^^^^^^
AttributeError: 'tuple' object has no attribute 'strip'
2025-08-11 11:49:53,573 | src.biotech_pipeline.extractors.base_extractor | ERROR | Max retries exceeded for _fetch_serper: Serper API error
2025-08-11 11:49:54,315 | src.biotech_pipeline.pipeline.etl_orchestrator | CRITICAL | Unexpected error for BIRAC/CCAMP01917/BIG-21/22: 'tuple' object has no attribute 'strip'
Traceback (most recent call last):
  File "/Users/kaushalprajapati/Desktop/Development/BiD_Indian_BT_startups/src/biotech_pipeline/pipeline/etl_orchestrator.py", line 65, in run
    payloads = self.processor.prepare_payloads(
               ^^^^^^^^^^^^^^^^^^^^^^^^^^^^^^^^
  File "/Users/kaushalprajapati/Desktop/Development/BiD_Indian_BT_startups/src/biotech_pipeline/processors/data_processor.py", line 61, in prepare_payloads
    "cin": validate_cin(consolidated.get("cin") or ""),
           ^^^^^^^^^^^^^^^^^^^^^^^^^^^^^^^^^^^^^^^^^^^
  File "/Users/kaushalprajapati/Desktop/Development/BiD_Indian_BT_startups/src/biotech_pipeline/processors/data_cleaner.py", line 92, in validate_cin
    cin = cin.strip().upper()
          ^^^^^^^^^
AttributeError: 'tuple' object has no attribute 'strip'
2025-08-11 11:51:10,938 | src.biotech_pipeline.extractors.base_extractor | ERROR | Max retries exceeded for _fetch_serper: Serper API error
2025-08-11 11:51:11,677 | src.biotech_pipeline.pipeline.etl_orchestrator | CRITICAL | Unexpected error for BIRAC/KIIT01604/BIG-20/22: 'tuple' object has no attribute 'strip'
Traceback (most recent call last):
  File "/Users/kaushalprajapati/Desktop/Development/BiD_Indian_BT_startups/src/biotech_pipeline/pipeline/etl_orchestrator.py", line 65, in run
    payloads = self.processor.prepare_payloads(
               ^^^^^^^^^^^^^^^^^^^^^^^^^^^^^^^^
  File "/Users/kaushalprajapati/Desktop/Development/BiD_Indian_BT_startups/src/biotech_pipeline/processors/data_processor.py", line 61, in prepare_payloads
    "cin": validate_cin(consolidated.get("cin") or ""),
           ^^^^^^^^^^^^^^^^^^^^^^^^^^^^^^^^^^^^^^^^^^^
  File "/Users/kaushalprajapati/Desktop/Development/BiD_Indian_BT_startups/src/biotech_pipeline/processors/data_cleaner.py", line 92, in validate_cin
    cin = cin.strip().upper()
          ^^^^^^^^^
AttributeError: 'tuple' object has no attribute 'strip'
2025-08-11 11:52:02,955 | src.biotech_pipeline.extractors.website_scraper | ERROR | WebsiteExtractor network error: HTTPSConnectionPool(host='www.innodxsolutions.com', port=443): Max retries exceeded with url: / (Caused by NameResolutionError("<urllib3.connection.HTTPSConnection object at 0x11fac5d00>: Failed to resolve 'www.innodxsolutions.com' ([Errno 8] nodename nor servname provided, or not known)"))
2025-08-11 11:52:22,343 | src.biotech_pipeline.extractors.base_extractor | ERROR | Max retries exceeded for _fetch_serper: Serper API error
2025-08-11 11:52:23,034 | src.biotech_pipeline.pipeline.etl_orchestrator | CRITICAL | Unexpected error for BIRAC/VENTURE0864/BIG-20/22: 'tuple' object has no attribute 'strip'
Traceback (most recent call last):
  File "/Users/kaushalprajapati/Desktop/Development/BiD_Indian_BT_startups/src/biotech_pipeline/pipeline/etl_orchestrator.py", line 65, in run
    payloads = self.processor.prepare_payloads(
               ^^^^^^^^^^^^^^^^^^^^^^^^^^^^^^^^
  File "/Users/kaushalprajapati/Desktop/Development/BiD_Indian_BT_startups/src/biotech_pipeline/processors/data_processor.py", line 61, in prepare_payloads
    "cin": validate_cin(consolidated.get("cin") or ""),
           ^^^^^^^^^^^^^^^^^^^^^^^^^^^^^^^^^^^^^^^^^^^
  File "/Users/kaushalprajapati/Desktop/Development/BiD_Indian_BT_startups/src/biotech_pipeline/processors/data_cleaner.py", line 92, in validate_cin
    cin = cin.strip().upper()
          ^^^^^^^^^
AttributeError: 'tuple' object has no attribute 'strip'
2025-08-11 11:54:06,962 | src.biotech_pipeline.extractors.base_extractor | ERROR | Max retries exceeded for _fetch_serper: Serper API error
2025-08-11 11:54:07,760 | src.biotech_pipeline.pipeline.etl_orchestrator | CRITICAL | Unexpected error for BIRAC/CCAMP01675/BIG-19/21: 'tuple' object has no attribute 'strip'
Traceback (most recent call last):
  File "/Users/kaushalprajapati/Desktop/Development/BiD_Indian_BT_startups/src/biotech_pipeline/pipeline/etl_orchestrator.py", line 65, in run
    payloads = self.processor.prepare_payloads(
               ^^^^^^^^^^^^^^^^^^^^^^^^^^^^^^^^
  File "/Users/kaushalprajapati/Desktop/Development/BiD_Indian_BT_startups/src/biotech_pipeline/processors/data_processor.py", line 61, in prepare_payloads
    "cin": validate_cin(consolidated.get("cin") or ""),
           ^^^^^^^^^^^^^^^^^^^^^^^^^^^^^^^^^^^^^^^^^^^
  File "/Users/kaushalprajapati/Desktop/Development/BiD_Indian_BT_startups/src/biotech_pipeline/processors/data_cleaner.py", line 92, in validate_cin
    cin = cin.strip().upper()
          ^^^^^^^^^
AttributeError: 'tuple' object has no attribute 'strip'
2025-08-11 11:59:20,730 | src.biotech_pipeline.extractors.base_extractor | ERROR | Max retries exceeded for _fetch_serper: Serper API error
2025-08-11 11:59:21,476 | src.biotech_pipeline.agents.validation_agent | ERROR | Operation failed: src.biotech_pipeline.agents.validation_agent.validate_complete_profile (duration: 0.001s) - Error: Unknown entity type: news_coverage
Traceback (most recent call last):
  File "/Users/kaushalprajapati/Desktop/Development/BiD_Indian_BT_startups/src/biotech_pipeline/utils/logger.py", line 59, in wrapper
    result = func(*args, **kwargs)
             ^^^^^^^^^^^^^^^^^^^^^
  File "/Users/kaushalprajapati/Desktop/Development/BiD_Indian_BT_startups/src/biotech_pipeline/agents/validation_agent.py", line 63, in validate_complete_profile
    entity_results = self._validate_entity_list(entity_type, entity_data_list)
                     ^^^^^^^^^^^^^^^^^^^^^^^^^^^^^^^^^^^^^^^^^^^^^^^^^^^^^^^^^
  File "/Users/kaushalprajapati/Desktop/Development/BiD_Indian_BT_startups/src/biotech_pipeline/agents/validation_agent.py", line 115, in _validate_entity_list
    validation_results = self.validator.validate_entity(entity_type, entity_data)
                         ^^^^^^^^^^^^^^^^^^^^^^^^^^^^^^^^^^^^^^^^^^^^^^^^^^^^^^^^
  File "/Users/kaushalprajapati/Desktop/Development/BiD_Indian_BT_startups/src/biotech_pipeline/processors/validator.py", line 312, in validate_entity
    raise ValidationError(
src.biotech_pipeline.utils.exceptions.ValidationError: Unknown entity type: news_coverage
2025-08-11 11:59:21,480 | src.biotech_pipeline.pipeline.etl_orchestrator | ERROR | Validation agent crashed for BIRAC/KIIT02236/BIG-23/23: Unknown entity type: news_coverage
Traceback (most recent call last):
  File "/Users/kaushalprajapati/Desktop/Development/BiD_Indian_BT_startups/src/biotech_pipeline/pipeline/etl_orchestrator.py", line 72, in run
    valid, report = validation_agent.validate_complete_profile(bid, payloads)
                    ^^^^^^^^^^^^^^^^^^^^^^^^^^^^^^^^^^^^^^^^^^^^^^^^^^^^^^^^^
  File "/Users/kaushalprajapati/Desktop/Development/BiD_Indian_BT_startups/src/biotech_pipeline/utils/logger.py", line 59, in wrapper
    result = func(*args, **kwargs)
             ^^^^^^^^^^^^^^^^^^^^^
  File "/Users/kaushalprajapati/Desktop/Development/BiD_Indian_BT_startups/src/biotech_pipeline/agents/validation_agent.py", line 63, in validate_complete_profile
    entity_results = self._validate_entity_list(entity_type, entity_data_list)
                     ^^^^^^^^^^^^^^^^^^^^^^^^^^^^^^^^^^^^^^^^^^^^^^^^^^^^^^^^^
  File "/Users/kaushalprajapati/Desktop/Development/BiD_Indian_BT_startups/src/biotech_pipeline/agents/validation_agent.py", line 115, in _validate_entity_list
    validation_results = self.validator.validate_entity(entity_type, entity_data)
                         ^^^^^^^^^^^^^^^^^^^^^^^^^^^^^^^^^^^^^^^^^^^^^^^^^^^^^^^^
  File "/Users/kaushalprajapati/Desktop/Development/BiD_Indian_BT_startups/src/biotech_pipeline/processors/validator.py", line 312, in validate_entity
    raise ValidationError(
src.biotech_pipeline.utils.exceptions.ValidationError: Unknown entity type: news_coverage
2025-08-11 12:07:38,182 | src.biotech_pipeline.extractors.base_extractor | ERROR | Max retries exceeded for _fetch_serper: Serper API error
2025-08-11 12:07:38,945 | src.biotech_pipeline.agents.validation_agent | ERROR | Operation failed: src.biotech_pipeline.agents.validation_agent.validate_complete_profile (duration: 0.000s) - Error: Unknown entity type: news_coverage
Traceback (most recent call last):
  File "/Users/kaushalprajapati/Desktop/Development/BiD_Indian_BT_startups/src/biotech_pipeline/utils/logger.py", line 59, in wrapper
    result = func(*args, **kwargs)
             ^^^^^^^^^^^^^^^^^^^^^
  File "/Users/kaushalprajapati/Desktop/Development/BiD_Indian_BT_startups/src/biotech_pipeline/agents/validation_agent.py", line 63, in validate_complete_profile
    entity_results = self._validate_entity_list(entity_type, entity_data_list)
                     ^^^^^^^^^^^^^^^^^^^^^^^^^^^^^^^^^^^^^^^^^^^^^^^^^^^^^^^^^
  File "/Users/kaushalprajapati/Desktop/Development/BiD_Indian_BT_startups/src/biotech_pipeline/agents/validation_agent.py", line 115, in _validate_entity_list
    validation_results = self.validator.validate_entity(entity_type, entity_data)
                         ^^^^^^^^^^^^^^^^^^^^^^^^^^^^^^^^^^^^^^^^^^^^^^^^^^^^^^^^
  File "/Users/kaushalprajapati/Desktop/Development/BiD_Indian_BT_startups/src/biotech_pipeline/processors/validator.py", line 312, in validate_entity
    raise ValidationError(
src.biotech_pipeline.utils.exceptions.ValidationError: Unknown entity type: news_coverage
2025-08-11 12:07:38,948 | src.biotech_pipeline.pipeline.etl_orchestrator | ERROR | Validation agent crashed for BIRAC/KIIT02236/BIG-23/23: Unknown entity type: news_coverage
Traceback (most recent call last):
  File "/Users/kaushalprajapati/Desktop/Development/BiD_Indian_BT_startups/src/biotech_pipeline/pipeline/etl_orchestrator.py", line 72, in run
    valid, report = validation_agent.validate_complete_profile(bid, payloads)
                    ^^^^^^^^^^^^^^^^^^^^^^^^^^^^^^^^^^^^^^^^^^^^^^^^^^^^^^^^^
  File "/Users/kaushalprajapati/Desktop/Development/BiD_Indian_BT_startups/src/biotech_pipeline/utils/logger.py", line 59, in wrapper
    result = func(*args, **kwargs)
             ^^^^^^^^^^^^^^^^^^^^^
  File "/Users/kaushalprajapati/Desktop/Development/BiD_Indian_BT_startups/src/biotech_pipeline/agents/validation_agent.py", line 63, in validate_complete_profile
    entity_results = self._validate_entity_list(entity_type, entity_data_list)
                     ^^^^^^^^^^^^^^^^^^^^^^^^^^^^^^^^^^^^^^^^^^^^^^^^^^^^^^^^^
  File "/Users/kaushalprajapati/Desktop/Development/BiD_Indian_BT_startups/src/biotech_pipeline/agents/validation_agent.py", line 115, in _validate_entity_list
    validation_results = self.validator.validate_entity(entity_type, entity_data)
                         ^^^^^^^^^^^^^^^^^^^^^^^^^^^^^^^^^^^^^^^^^^^^^^^^^^^^^^^^
  File "/Users/kaushalprajapati/Desktop/Development/BiD_Indian_BT_startups/src/biotech_pipeline/processors/validator.py", line 312, in validate_entity
    raise ValidationError(
src.biotech_pipeline.utils.exceptions.ValidationError: Unknown entity type: news_coverage
2025-08-11 12:08:27,376 | src.biotech_pipeline.extractors.base_extractor | ERROR | Max retries exceeded for _fetch_serper: Serper API error
2025-08-11 12:08:28,252 | src.biotech_pipeline.pipeline.etl_orchestrator | CRITICAL | Unexpected error for BIRAC/SINE0709/BIG-23/23: 'tuple' object has no attribute 'strip'
Traceback (most recent call last):
  File "/Users/kaushalprajapati/Desktop/Development/BiD_Indian_BT_startups/src/biotech_pipeline/pipeline/etl_orchestrator.py", line 65, in run
    payloads = self.processor.prepare_payloads(
               ^^^^^^^^^^^^^^^^^^^^^^^^^^^^^^^^
  File "/Users/kaushalprajapati/Desktop/Development/BiD_Indian_BT_startups/src/biotech_pipeline/processors/data_processor.py", line 63, in prepare_payloads
    "location": extract_location(consolidated.get("location") or ""),
                ^^^^^^^^^^^^^^^^^^^^^^^^^^^^^^^^^^^^^^^^^^^^^^^^^^^^
  File "/Users/kaushalprajapati/Desktop/Development/BiD_Indian_BT_startups/src/biotech_pipeline/processors/data_cleaner.py", line 81, in extract_location
    loc = " ".join(location_str.strip().split())
                   ^^^^^^^^^^^^^^^^^^
AttributeError: 'tuple' object has no attribute 'strip'
2025-08-11 12:09:24,905 | src.biotech_pipeline.extractors.web_extractor | ERROR | Patent fetch failed for Mabgenex Private Limited: HTTPSConnectionPool(host='patentscope.wipo.int', port=443): Max retries exceeded with url: /search/en/result.jsf?query=Mabgenex%20Private%20Limited (Caused by ConnectTimeoutError(<urllib3.connection.HTTPSConnection object at 0x115a06720>, 'Connection to patentscope.wipo.int timed out. (connect timeout=10)'))
2025-08-11 12:09:41,721 | src.biotech_pipeline.extractors.base_extractor | ERROR | Max retries exceeded for _fetch_serper: Serper API error
2025-08-11 12:09:42,588 | src.biotech_pipeline.pipeline.etl_orchestrator | CRITICAL | Unexpected error for BIRAC/SIIC0882/BIG-22/23: 'tuple' object has no attribute 'strip'
Traceback (most recent call last):
  File "/Users/kaushalprajapati/Desktop/Development/BiD_Indian_BT_startups/src/biotech_pipeline/pipeline/etl_orchestrator.py", line 65, in run
    payloads = self.processor.prepare_payloads(
               ^^^^^^^^^^^^^^^^^^^^^^^^^^^^^^^^
  File "/Users/kaushalprajapati/Desktop/Development/BiD_Indian_BT_startups/src/biotech_pipeline/processors/data_processor.py", line 63, in prepare_payloads
    "location": extract_location(consolidated.get("location") or ""),
                ^^^^^^^^^^^^^^^^^^^^^^^^^^^^^^^^^^^^^^^^^^^^^^^^^^^^
  File "/Users/kaushalprajapati/Desktop/Development/BiD_Indian_BT_startups/src/biotech_pipeline/processors/data_cleaner.py", line 81, in extract_location
    loc = " ".join(location_str.strip().split())
                   ^^^^^^^^^^^^^^^^^^
AttributeError: 'tuple' object has no attribute 'strip'
2025-08-11 12:10:46,501 | src.biotech_pipeline.extractors.website_scraper | ERROR | WebsiteExtractor network error: HTTPSConnectionPool(host='www.cancrie.com', port=443): Max retries exceeded with url: / (Caused by ConnectTimeoutError(<urllib3.connection.HTTPSConnection object at 0x11593ffb0>, 'Connection to www.cancrie.com timed out. (connect timeout=10)'))
2025-08-11 12:11:10,115 | src.biotech_pipeline.extractors.base_extractor | ERROR | Max retries exceeded for _fetch_serper: Serper API error
2025-08-11 12:11:10,906 | src.biotech_pipeline.pipeline.etl_orchestrator | CRITICAL | Unexpected error for BIRAC/IKP01696/BIG-22/23: 'tuple' object has no attribute 'strip'
Traceback (most recent call last):
  File "/Users/kaushalprajapati/Desktop/Development/BiD_Indian_BT_startups/src/biotech_pipeline/pipeline/etl_orchestrator.py", line 65, in run
    payloads = self.processor.prepare_payloads(
               ^^^^^^^^^^^^^^^^^^^^^^^^^^^^^^^^
  File "/Users/kaushalprajapati/Desktop/Development/BiD_Indian_BT_startups/src/biotech_pipeline/processors/data_processor.py", line 63, in prepare_payloads
    "location": extract_location(consolidated.get("location") or ""),
                ^^^^^^^^^^^^^^^^^^^^^^^^^^^^^^^^^^^^^^^^^^^^^^^^^^^^
  File "/Users/kaushalprajapati/Desktop/Development/BiD_Indian_BT_startups/src/biotech_pipeline/processors/data_cleaner.py", line 81, in extract_location
    loc = " ".join(location_str.strip().split())
                   ^^^^^^^^^^^^^^^^^^
AttributeError: 'tuple' object has no attribute 'strip'
2025-08-11 12:12:14,094 | src.biotech_pipeline.extractors.base_extractor | ERROR | Max retries exceeded for _fetch_serper: Serper API error
2025-08-11 12:12:14,857 | src.biotech_pipeline.pipeline.etl_orchestrator | CRITICAL | Unexpected error for BIRAC/IKP01613/BIG-21/22: 'tuple' object has no attribute 'strip'
Traceback (most recent call last):
  File "/Users/kaushalprajapati/Desktop/Development/BiD_Indian_BT_startups/src/biotech_pipeline/pipeline/etl_orchestrator.py", line 65, in run
    payloads = self.processor.prepare_payloads(
               ^^^^^^^^^^^^^^^^^^^^^^^^^^^^^^^^
  File "/Users/kaushalprajapati/Desktop/Development/BiD_Indian_BT_startups/src/biotech_pipeline/processors/data_processor.py", line 63, in prepare_payloads
    "location": extract_location(consolidated.get("location") or ""),
                ^^^^^^^^^^^^^^^^^^^^^^^^^^^^^^^^^^^^^^^^^^^^^^^^^^^^
  File "/Users/kaushalprajapati/Desktop/Development/BiD_Indian_BT_startups/src/biotech_pipeline/processors/data_cleaner.py", line 81, in extract_location
    loc = " ".join(location_str.strip().split())
                   ^^^^^^^^^^^^^^^^^^
AttributeError: 'tuple' object has no attribute 'strip'
2025-08-11 12:13:14,993 | src.biotech_pipeline.extractors.base_extractor | ERROR | Max retries exceeded for _fetch_serper: Serper API error
2025-08-11 12:13:15,741 | src.biotech_pipeline.pipeline.etl_orchestrator | CRITICAL | Unexpected error for BIRAC/CCAMP01917/BIG-21/22: 'tuple' object has no attribute 'strip'
Traceback (most recent call last):
  File "/Users/kaushalprajapati/Desktop/Development/BiD_Indian_BT_startups/src/biotech_pipeline/pipeline/etl_orchestrator.py", line 65, in run
    payloads = self.processor.prepare_payloads(
               ^^^^^^^^^^^^^^^^^^^^^^^^^^^^^^^^
  File "/Users/kaushalprajapati/Desktop/Development/BiD_Indian_BT_startups/src/biotech_pipeline/processors/data_processor.py", line 63, in prepare_payloads
    "location": extract_location(consolidated.get("location") or ""),
                ^^^^^^^^^^^^^^^^^^^^^^^^^^^^^^^^^^^^^^^^^^^^^^^^^^^^
  File "/Users/kaushalprajapati/Desktop/Development/BiD_Indian_BT_startups/src/biotech_pipeline/processors/data_cleaner.py", line 81, in extract_location
    loc = " ".join(location_str.strip().split())
                   ^^^^^^^^^^^^^^^^^^
AttributeError: 'tuple' object has no attribute 'strip'
2025-08-11 12:15:22,101 | src.biotech_pipeline.extractors.base_extractor | ERROR | Max retries exceeded for _fetch_serper: Serper API error
2025-08-11 12:16:24,566 | src.biotech_pipeline.extractors.base_extractor | ERROR | Max retries exceeded for _fetch_serper: Serper API error
2025-08-11 12:16:25,255 | src.biotech_pipeline.agents.validation_agent | ERROR | Operation failed: src.biotech_pipeline.agents.validation_agent.validate_complete_profile (duration: 0.000s) - Error: Unknown entity type: people
Traceback (most recent call last):
  File "/Users/kaushalprajapati/Desktop/Development/BiD_Indian_BT_startups/src/biotech_pipeline/utils/logger.py", line 59, in wrapper
    result = func(*args, **kwargs)
             ^^^^^^^^^^^^^^^^^^^^^
  File "/Users/kaushalprajapati/Desktop/Development/BiD_Indian_BT_startups/src/biotech_pipeline/agents/validation_agent.py", line 63, in validate_complete_profile
    entity_results = self._validate_entity_list(entity_type, entity_data_list)
                     ^^^^^^^^^^^^^^^^^^^^^^^^^^^^^^^^^^^^^^^^^^^^^^^^^^^^^^^^^
  File "/Users/kaushalprajapati/Desktop/Development/BiD_Indian_BT_startups/src/biotech_pipeline/agents/validation_agent.py", line 115, in _validate_entity_list
    validation_results = self.validator.validate_entity(entity_type, entity_data)
                         ^^^^^^^^^^^^^^^^^^^^^^^^^^^^^^^^^^^^^^^^^^^^^^^^^^^^^^^^
  File "/Users/kaushalprajapati/Desktop/Development/BiD_Indian_BT_startups/src/biotech_pipeline/processors/validator.py", line 317, in validate_entity
    raise ValidationError(
src.biotech_pipeline.utils.exceptions.ValidationError: Unknown entity type: people
2025-08-11 12:16:25,258 | src.biotech_pipeline.pipeline.etl_orchestrator | ERROR | Validation agent crashed for BIRAC/SINE0709/BIG-23/23: Unknown entity type: people
Traceback (most recent call last):
  File "/Users/kaushalprajapati/Desktop/Development/BiD_Indian_BT_startups/src/biotech_pipeline/pipeline/etl_orchestrator.py", line 72, in run
    valid, report = validation_agent.validate_complete_profile(bid, payloads)
                    ^^^^^^^^^^^^^^^^^^^^^^^^^^^^^^^^^^^^^^^^^^^^^^^^^^^^^^^^^
  File "/Users/kaushalprajapati/Desktop/Development/BiD_Indian_BT_startups/src/biotech_pipeline/utils/logger.py", line 59, in wrapper
    result = func(*args, **kwargs)
             ^^^^^^^^^^^^^^^^^^^^^
  File "/Users/kaushalprajapati/Desktop/Development/BiD_Indian_BT_startups/src/biotech_pipeline/agents/validation_agent.py", line 63, in validate_complete_profile
    entity_results = self._validate_entity_list(entity_type, entity_data_list)
                     ^^^^^^^^^^^^^^^^^^^^^^^^^^^^^^^^^^^^^^^^^^^^^^^^^^^^^^^^^
  File "/Users/kaushalprajapati/Desktop/Development/BiD_Indian_BT_startups/src/biotech_pipeline/agents/validation_agent.py", line 115, in _validate_entity_list
    validation_results = self.validator.validate_entity(entity_type, entity_data)
                         ^^^^^^^^^^^^^^^^^^^^^^^^^^^^^^^^^^^^^^^^^^^^^^^^^^^^^^^^
  File "/Users/kaushalprajapati/Desktop/Development/BiD_Indian_BT_startups/src/biotech_pipeline/processors/validator.py", line 317, in validate_entity
    raise ValidationError(
src.biotech_pipeline.utils.exceptions.ValidationError: Unknown entity type: people
2025-08-11 12:17:28,752 | src.biotech_pipeline.extractors.base_extractor | ERROR | Max retries exceeded for _fetch_serper: Serper API error
2025-08-11 12:17:29,798 | src.biotech_pipeline.agents.validation_agent | ERROR | Operation failed: src.biotech_pipeline.agents.validation_agent.validate_complete_profile (duration: 0.000s) - Error: Unknown entity type: people
Traceback (most recent call last):
  File "/Users/kaushalprajapati/Desktop/Development/BiD_Indian_BT_startups/src/biotech_pipeline/utils/logger.py", line 59, in wrapper
    result = func(*args, **kwargs)
             ^^^^^^^^^^^^^^^^^^^^^
  File "/Users/kaushalprajapati/Desktop/Development/BiD_Indian_BT_startups/src/biotech_pipeline/agents/validation_agent.py", line 63, in validate_complete_profile
    entity_results = self._validate_entity_list(entity_type, entity_data_list)
                     ^^^^^^^^^^^^^^^^^^^^^^^^^^^^^^^^^^^^^^^^^^^^^^^^^^^^^^^^^
  File "/Users/kaushalprajapati/Desktop/Development/BiD_Indian_BT_startups/src/biotech_pipeline/agents/validation_agent.py", line 115, in _validate_entity_list
    validation_results = self.validator.validate_entity(entity_type, entity_data)
                         ^^^^^^^^^^^^^^^^^^^^^^^^^^^^^^^^^^^^^^^^^^^^^^^^^^^^^^^^
  File "/Users/kaushalprajapati/Desktop/Development/BiD_Indian_BT_startups/src/biotech_pipeline/processors/validator.py", line 317, in validate_entity
    raise ValidationError(
src.biotech_pipeline.utils.exceptions.ValidationError: Unknown entity type: people
2025-08-11 12:17:29,798 | src.biotech_pipeline.pipeline.etl_orchestrator | ERROR | Validation agent crashed for BIRAC/SIIC0882/BIG-22/23: Unknown entity type: people
Traceback (most recent call last):
  File "/Users/kaushalprajapati/Desktop/Development/BiD_Indian_BT_startups/src/biotech_pipeline/pipeline/etl_orchestrator.py", line 72, in run
    valid, report = validation_agent.validate_complete_profile(bid, payloads)
                    ^^^^^^^^^^^^^^^^^^^^^^^^^^^^^^^^^^^^^^^^^^^^^^^^^^^^^^^^^
  File "/Users/kaushalprajapati/Desktop/Development/BiD_Indian_BT_startups/src/biotech_pipeline/utils/logger.py", line 59, in wrapper
    result = func(*args, **kwargs)
             ^^^^^^^^^^^^^^^^^^^^^
  File "/Users/kaushalprajapati/Desktop/Development/BiD_Indian_BT_startups/src/biotech_pipeline/agents/validation_agent.py", line 63, in validate_complete_profile
    entity_results = self._validate_entity_list(entity_type, entity_data_list)
                     ^^^^^^^^^^^^^^^^^^^^^^^^^^^^^^^^^^^^^^^^^^^^^^^^^^^^^^^^^
  File "/Users/kaushalprajapati/Desktop/Development/BiD_Indian_BT_startups/src/biotech_pipeline/agents/validation_agent.py", line 115, in _validate_entity_list
    validation_results = self.validator.validate_entity(entity_type, entity_data)
                         ^^^^^^^^^^^^^^^^^^^^^^^^^^^^^^^^^^^^^^^^^^^^^^^^^^^^^^^^
  File "/Users/kaushalprajapati/Desktop/Development/BiD_Indian_BT_startups/src/biotech_pipeline/processors/validator.py", line 317, in validate_entity
    raise ValidationError(
src.biotech_pipeline.utils.exceptions.ValidationError: Unknown entity type: people
2025-08-11 12:18:26,250 | src.biotech_pipeline.extractors.website_scraper | ERROR | WebsiteExtractor network error: HTTPSConnectionPool(host='www.cancrie.com', port=443): Max retries exceeded with url: / (Caused by ConnectTimeoutError(<urllib3.connection.HTTPSConnection object at 0x10f2b0410>, 'Connection to www.cancrie.com timed out. (connect timeout=10)'))
2025-08-11 12:18:44,634 | src.biotech_pipeline.extractors.base_extractor | ERROR | Max retries exceeded for _fetch_serper: Serper API error
2025-08-11 12:18:45,579 | src.biotech_pipeline.agents.validation_agent | ERROR | Operation failed: src.biotech_pipeline.agents.validation_agent.validate_complete_profile (duration: 0.000s) - Error: Unknown entity type: people
Traceback (most recent call last):
  File "/Users/kaushalprajapati/Desktop/Development/BiD_Indian_BT_startups/src/biotech_pipeline/utils/logger.py", line 59, in wrapper
    result = func(*args, **kwargs)
             ^^^^^^^^^^^^^^^^^^^^^
  File "/Users/kaushalprajapati/Desktop/Development/BiD_Indian_BT_startups/src/biotech_pipeline/agents/validation_agent.py", line 63, in validate_complete_profile
    entity_results = self._validate_entity_list(entity_type, entity_data_list)
                     ^^^^^^^^^^^^^^^^^^^^^^^^^^^^^^^^^^^^^^^^^^^^^^^^^^^^^^^^^
  File "/Users/kaushalprajapati/Desktop/Development/BiD_Indian_BT_startups/src/biotech_pipeline/agents/validation_agent.py", line 115, in _validate_entity_list
    validation_results = self.validator.validate_entity(entity_type, entity_data)
                         ^^^^^^^^^^^^^^^^^^^^^^^^^^^^^^^^^^^^^^^^^^^^^^^^^^^^^^^^
  File "/Users/kaushalprajapati/Desktop/Development/BiD_Indian_BT_startups/src/biotech_pipeline/processors/validator.py", line 317, in validate_entity
    raise ValidationError(
src.biotech_pipeline.utils.exceptions.ValidationError: Unknown entity type: people
2025-08-11 12:18:45,580 | src.biotech_pipeline.pipeline.etl_orchestrator | ERROR | Validation agent crashed for BIRAC/IKP01696/BIG-22/23: Unknown entity type: people
Traceback (most recent call last):
  File "/Users/kaushalprajapati/Desktop/Development/BiD_Indian_BT_startups/src/biotech_pipeline/pipeline/etl_orchestrator.py", line 72, in run
    valid, report = validation_agent.validate_complete_profile(bid, payloads)
                    ^^^^^^^^^^^^^^^^^^^^^^^^^^^^^^^^^^^^^^^^^^^^^^^^^^^^^^^^^
  File "/Users/kaushalprajapati/Desktop/Development/BiD_Indian_BT_startups/src/biotech_pipeline/utils/logger.py", line 59, in wrapper
    result = func(*args, **kwargs)
             ^^^^^^^^^^^^^^^^^^^^^
  File "/Users/kaushalprajapati/Desktop/Development/BiD_Indian_BT_startups/src/biotech_pipeline/agents/validation_agent.py", line 63, in validate_complete_profile
    entity_results = self._validate_entity_list(entity_type, entity_data_list)
                     ^^^^^^^^^^^^^^^^^^^^^^^^^^^^^^^^^^^^^^^^^^^^^^^^^^^^^^^^^
  File "/Users/kaushalprajapati/Desktop/Development/BiD_Indian_BT_startups/src/biotech_pipeline/agents/validation_agent.py", line 115, in _validate_entity_list
    validation_results = self.validator.validate_entity(entity_type, entity_data)
                         ^^^^^^^^^^^^^^^^^^^^^^^^^^^^^^^^^^^^^^^^^^^^^^^^^^^^^^^^
  File "/Users/kaushalprajapati/Desktop/Development/BiD_Indian_BT_startups/src/biotech_pipeline/processors/validator.py", line 317, in validate_entity
    raise ValidationError(
src.biotech_pipeline.utils.exceptions.ValidationError: Unknown entity type: people
2025-08-11 12:19:40,002 | src.biotech_pipeline.extractors.base_extractor | ERROR | Max retries exceeded for _fetch_serper: Serper API error
2025-08-11 12:19:41,079 | src.biotech_pipeline.agents.validation_agent | ERROR | Operation failed: src.biotech_pipeline.agents.validation_agent.validate_complete_profile (duration: 0.000s) - Error: Unknown entity type: people
Traceback (most recent call last):
  File "/Users/kaushalprajapati/Desktop/Development/BiD_Indian_BT_startups/src/biotech_pipeline/utils/logger.py", line 59, in wrapper
    result = func(*args, **kwargs)
             ^^^^^^^^^^^^^^^^^^^^^
  File "/Users/kaushalprajapati/Desktop/Development/BiD_Indian_BT_startups/src/biotech_pipeline/agents/validation_agent.py", line 63, in validate_complete_profile
    entity_results = self._validate_entity_list(entity_type, entity_data_list)
                     ^^^^^^^^^^^^^^^^^^^^^^^^^^^^^^^^^^^^^^^^^^^^^^^^^^^^^^^^^
  File "/Users/kaushalprajapati/Desktop/Development/BiD_Indian_BT_startups/src/biotech_pipeline/agents/validation_agent.py", line 115, in _validate_entity_list
    validation_results = self.validator.validate_entity(entity_type, entity_data)
                         ^^^^^^^^^^^^^^^^^^^^^^^^^^^^^^^^^^^^^^^^^^^^^^^^^^^^^^^^
  File "/Users/kaushalprajapati/Desktop/Development/BiD_Indian_BT_startups/src/biotech_pipeline/processors/validator.py", line 317, in validate_entity
    raise ValidationError(
src.biotech_pipeline.utils.exceptions.ValidationError: Unknown entity type: people
2025-08-11 12:19:41,080 | src.biotech_pipeline.pipeline.etl_orchestrator | ERROR | Validation agent crashed for BIRAC/IKP01613/BIG-21/22: Unknown entity type: people
Traceback (most recent call last):
  File "/Users/kaushalprajapati/Desktop/Development/BiD_Indian_BT_startups/src/biotech_pipeline/pipeline/etl_orchestrator.py", line 72, in run
    valid, report = validation_agent.validate_complete_profile(bid, payloads)
                    ^^^^^^^^^^^^^^^^^^^^^^^^^^^^^^^^^^^^^^^^^^^^^^^^^^^^^^^^^
  File "/Users/kaushalprajapati/Desktop/Development/BiD_Indian_BT_startups/src/biotech_pipeline/utils/logger.py", line 59, in wrapper
    result = func(*args, **kwargs)
             ^^^^^^^^^^^^^^^^^^^^^
  File "/Users/kaushalprajapati/Desktop/Development/BiD_Indian_BT_startups/src/biotech_pipeline/agents/validation_agent.py", line 63, in validate_complete_profile
    entity_results = self._validate_entity_list(entity_type, entity_data_list)
                     ^^^^^^^^^^^^^^^^^^^^^^^^^^^^^^^^^^^^^^^^^^^^^^^^^^^^^^^^^
  File "/Users/kaushalprajapati/Desktop/Development/BiD_Indian_BT_startups/src/biotech_pipeline/agents/validation_agent.py", line 115, in _validate_entity_list
    validation_results = self.validator.validate_entity(entity_type, entity_data)
                         ^^^^^^^^^^^^^^^^^^^^^^^^^^^^^^^^^^^^^^^^^^^^^^^^^^^^^^^^
  File "/Users/kaushalprajapati/Desktop/Development/BiD_Indian_BT_startups/src/biotech_pipeline/processors/validator.py", line 317, in validate_entity
    raise ValidationError(
src.biotech_pipeline.utils.exceptions.ValidationError: Unknown entity type: people
2025-08-11 12:20:35,352 | src.biotech_pipeline.extractors.base_extractor | ERROR | Max retries exceeded for _fetch_serper: Serper API error
2025-08-11 12:20:36,377 | src.biotech_pipeline.agents.validation_agent | ERROR | Operation failed: src.biotech_pipeline.agents.validation_agent.validate_complete_profile (duration: 0.000s) - Error: Unknown entity type: people
Traceback (most recent call last):
  File "/Users/kaushalprajapati/Desktop/Development/BiD_Indian_BT_startups/src/biotech_pipeline/utils/logger.py", line 59, in wrapper
    result = func(*args, **kwargs)
             ^^^^^^^^^^^^^^^^^^^^^
  File "/Users/kaushalprajapati/Desktop/Development/BiD_Indian_BT_startups/src/biotech_pipeline/agents/validation_agent.py", line 63, in validate_complete_profile
    entity_results = self._validate_entity_list(entity_type, entity_data_list)
                     ^^^^^^^^^^^^^^^^^^^^^^^^^^^^^^^^^^^^^^^^^^^^^^^^^^^^^^^^^
  File "/Users/kaushalprajapati/Desktop/Development/BiD_Indian_BT_startups/src/biotech_pipeline/agents/validation_agent.py", line 115, in _validate_entity_list
    validation_results = self.validator.validate_entity(entity_type, entity_data)
                         ^^^^^^^^^^^^^^^^^^^^^^^^^^^^^^^^^^^^^^^^^^^^^^^^^^^^^^^^
  File "/Users/kaushalprajapati/Desktop/Development/BiD_Indian_BT_startups/src/biotech_pipeline/processors/validator.py", line 317, in validate_entity
    raise ValidationError(
src.biotech_pipeline.utils.exceptions.ValidationError: Unknown entity type: people
2025-08-11 12:20:36,378 | src.biotech_pipeline.pipeline.etl_orchestrator | ERROR | Validation agent crashed for BIRAC/CCAMP01917/BIG-21/22: Unknown entity type: people
Traceback (most recent call last):
  File "/Users/kaushalprajapati/Desktop/Development/BiD_Indian_BT_startups/src/biotech_pipeline/pipeline/etl_orchestrator.py", line 72, in run
    valid, report = validation_agent.validate_complete_profile(bid, payloads)
                    ^^^^^^^^^^^^^^^^^^^^^^^^^^^^^^^^^^^^^^^^^^^^^^^^^^^^^^^^^
  File "/Users/kaushalprajapati/Desktop/Development/BiD_Indian_BT_startups/src/biotech_pipeline/utils/logger.py", line 59, in wrapper
    result = func(*args, **kwargs)
             ^^^^^^^^^^^^^^^^^^^^^
  File "/Users/kaushalprajapati/Desktop/Development/BiD_Indian_BT_startups/src/biotech_pipeline/agents/validation_agent.py", line 63, in validate_complete_profile
    entity_results = self._validate_entity_list(entity_type, entity_data_list)
                     ^^^^^^^^^^^^^^^^^^^^^^^^^^^^^^^^^^^^^^^^^^^^^^^^^^^^^^^^^
  File "/Users/kaushalprajapati/Desktop/Development/BiD_Indian_BT_startups/src/biotech_pipeline/agents/validation_agent.py", line 115, in _validate_entity_list
    validation_results = self.validator.validate_entity(entity_type, entity_data)
                         ^^^^^^^^^^^^^^^^^^^^^^^^^^^^^^^^^^^^^^^^^^^^^^^^^^^^^^^^
  File "/Users/kaushalprajapati/Desktop/Development/BiD_Indian_BT_startups/src/biotech_pipeline/processors/validator.py", line 317, in validate_entity
    raise ValidationError(
src.biotech_pipeline.utils.exceptions.ValidationError: Unknown entity type: people
2025-08-11 12:21:35,855 | src.biotech_pipeline.extractors.web_extractor | ERROR | Patent fetch failed for Inofinity Research and Development Private Limited: HTTPSConnectionPool(host='patentscope.wipo.int', port=443): Read timed out. (read timeout=10)
2025-08-11 12:21:52,713 | src.biotech_pipeline.extractors.base_extractor | ERROR | Max retries exceeded for _fetch_serper: Serper API error
2025-08-11 12:21:53,428 | src.biotech_pipeline.agents.validation_agent | ERROR | Operation failed: src.biotech_pipeline.agents.validation_agent.validate_complete_profile (duration: 0.001s) - Error: Unknown entity type: people
Traceback (most recent call last):
  File "/Users/kaushalprajapati/Desktop/Development/BiD_Indian_BT_startups/src/biotech_pipeline/utils/logger.py", line 59, in wrapper
    result = func(*args, **kwargs)
             ^^^^^^^^^^^^^^^^^^^^^
  File "/Users/kaushalprajapati/Desktop/Development/BiD_Indian_BT_startups/src/biotech_pipeline/agents/validation_agent.py", line 63, in validate_complete_profile
    entity_results = self._validate_entity_list(entity_type, entity_data_list)
                     ^^^^^^^^^^^^^^^^^^^^^^^^^^^^^^^^^^^^^^^^^^^^^^^^^^^^^^^^^
  File "/Users/kaushalprajapati/Desktop/Development/BiD_Indian_BT_startups/src/biotech_pipeline/agents/validation_agent.py", line 115, in _validate_entity_list
    validation_results = self.validator.validate_entity(entity_type, entity_data)
                         ^^^^^^^^^^^^^^^^^^^^^^^^^^^^^^^^^^^^^^^^^^^^^^^^^^^^^^^^
  File "/Users/kaushalprajapati/Desktop/Development/BiD_Indian_BT_startups/src/biotech_pipeline/processors/validator.py", line 317, in validate_entity
    raise ValidationError(
src.biotech_pipeline.utils.exceptions.ValidationError: Unknown entity type: people
2025-08-11 12:21:53,429 | src.biotech_pipeline.pipeline.etl_orchestrator | ERROR | Validation agent crashed for BIRAC/KIIT01604/BIG-20/22: Unknown entity type: people
Traceback (most recent call last):
  File "/Users/kaushalprajapati/Desktop/Development/BiD_Indian_BT_startups/src/biotech_pipeline/pipeline/etl_orchestrator.py", line 72, in run
    valid, report = validation_agent.validate_complete_profile(bid, payloads)
                    ^^^^^^^^^^^^^^^^^^^^^^^^^^^^^^^^^^^^^^^^^^^^^^^^^^^^^^^^^
  File "/Users/kaushalprajapati/Desktop/Development/BiD_Indian_BT_startups/src/biotech_pipeline/utils/logger.py", line 59, in wrapper
    result = func(*args, **kwargs)
             ^^^^^^^^^^^^^^^^^^^^^
  File "/Users/kaushalprajapati/Desktop/Development/BiD_Indian_BT_startups/src/biotech_pipeline/agents/validation_agent.py", line 63, in validate_complete_profile
    entity_results = self._validate_entity_list(entity_type, entity_data_list)
                     ^^^^^^^^^^^^^^^^^^^^^^^^^^^^^^^^^^^^^^^^^^^^^^^^^^^^^^^^^
  File "/Users/kaushalprajapati/Desktop/Development/BiD_Indian_BT_startups/src/biotech_pipeline/agents/validation_agent.py", line 115, in _validate_entity_list
    validation_results = self.validator.validate_entity(entity_type, entity_data)
                         ^^^^^^^^^^^^^^^^^^^^^^^^^^^^^^^^^^^^^^^^^^^^^^^^^^^^^^^^
  File "/Users/kaushalprajapati/Desktop/Development/BiD_Indian_BT_startups/src/biotech_pipeline/processors/validator.py", line 317, in validate_entity
    raise ValidationError(
src.biotech_pipeline.utils.exceptions.ValidationError: Unknown entity type: people
2025-08-11 12:22:35,896 | src.biotech_pipeline.extractors.website_scraper | ERROR | WebsiteExtractor network error: HTTPSConnectionPool(host='www.innodxsolutions.com', port=443): Max retries exceeded with url: / (Caused by NameResolutionError("<urllib3.connection.HTTPSConnection object at 0x10f2b2f00>: Failed to resolve 'www.innodxsolutions.com' ([Errno 8] nodename nor servname provided, or not known)"))
2025-08-11 12:22:53,756 | src.biotech_pipeline.extractors.base_extractor | ERROR | Max retries exceeded for _fetch_serper: Serper API error
2025-08-11 12:22:54,585 | src.biotech_pipeline.agents.validation_agent | ERROR | Operation failed: src.biotech_pipeline.agents.validation_agent.validate_complete_profile (duration: 0.000s) - Error: Unknown entity type: people
Traceback (most recent call last):
  File "/Users/kaushalprajapati/Desktop/Development/BiD_Indian_BT_startups/src/biotech_pipeline/utils/logger.py", line 59, in wrapper
    result = func(*args, **kwargs)
             ^^^^^^^^^^^^^^^^^^^^^
  File "/Users/kaushalprajapati/Desktop/Development/BiD_Indian_BT_startups/src/biotech_pipeline/agents/validation_agent.py", line 63, in validate_complete_profile
    entity_results = self._validate_entity_list(entity_type, entity_data_list)
                     ^^^^^^^^^^^^^^^^^^^^^^^^^^^^^^^^^^^^^^^^^^^^^^^^^^^^^^^^^
  File "/Users/kaushalprajapati/Desktop/Development/BiD_Indian_BT_startups/src/biotech_pipeline/agents/validation_agent.py", line 115, in _validate_entity_list
    validation_results = self.validator.validate_entity(entity_type, entity_data)
                         ^^^^^^^^^^^^^^^^^^^^^^^^^^^^^^^^^^^^^^^^^^^^^^^^^^^^^^^^
  File "/Users/kaushalprajapati/Desktop/Development/BiD_Indian_BT_startups/src/biotech_pipeline/processors/validator.py", line 317, in validate_entity
    raise ValidationError(
src.biotech_pipeline.utils.exceptions.ValidationError: Unknown entity type: people
2025-08-11 12:22:54,586 | src.biotech_pipeline.pipeline.etl_orchestrator | ERROR | Validation agent crashed for BIRAC/VENTURE0864/BIG-20/22: Unknown entity type: people
Traceback (most recent call last):
  File "/Users/kaushalprajapati/Desktop/Development/BiD_Indian_BT_startups/src/biotech_pipeline/pipeline/etl_orchestrator.py", line 72, in run
    valid, report = validation_agent.validate_complete_profile(bid, payloads)
                    ^^^^^^^^^^^^^^^^^^^^^^^^^^^^^^^^^^^^^^^^^^^^^^^^^^^^^^^^^
  File "/Users/kaushalprajapati/Desktop/Development/BiD_Indian_BT_startups/src/biotech_pipeline/utils/logger.py", line 59, in wrapper
    result = func(*args, **kwargs)
             ^^^^^^^^^^^^^^^^^^^^^
  File "/Users/kaushalprajapati/Desktop/Development/BiD_Indian_BT_startups/src/biotech_pipeline/agents/validation_agent.py", line 63, in validate_complete_profile
    entity_results = self._validate_entity_list(entity_type, entity_data_list)
                     ^^^^^^^^^^^^^^^^^^^^^^^^^^^^^^^^^^^^^^^^^^^^^^^^^^^^^^^^^
  File "/Users/kaushalprajapati/Desktop/Development/BiD_Indian_BT_startups/src/biotech_pipeline/agents/validation_agent.py", line 115, in _validate_entity_list
    validation_results = self.validator.validate_entity(entity_type, entity_data)
                         ^^^^^^^^^^^^^^^^^^^^^^^^^^^^^^^^^^^^^^^^^^^^^^^^^^^^^^^^
  File "/Users/kaushalprajapati/Desktop/Development/BiD_Indian_BT_startups/src/biotech_pipeline/processors/validator.py", line 317, in validate_entity
    raise ValidationError(
src.biotech_pipeline.utils.exceptions.ValidationError: Unknown entity type: people
2025-08-11 12:24:00,093 | src.biotech_pipeline.extractors.base_extractor | ERROR | Max retries exceeded for _fetch_serper: Serper API error
2025-08-11 12:24:00,975 | src.biotech_pipeline.agents.validation_agent | ERROR | Operation failed: src.biotech_pipeline.agents.validation_agent.validate_complete_profile (duration: 0.000s) - Error: Unknown entity type: people
Traceback (most recent call last):
  File "/Users/kaushalprajapati/Desktop/Development/BiD_Indian_BT_startups/src/biotech_pipeline/utils/logger.py", line 59, in wrapper
    result = func(*args, **kwargs)
             ^^^^^^^^^^^^^^^^^^^^^
  File "/Users/kaushalprajapati/Desktop/Development/BiD_Indian_BT_startups/src/biotech_pipeline/agents/validation_agent.py", line 63, in validate_complete_profile
    entity_results = self._validate_entity_list(entity_type, entity_data_list)
                     ^^^^^^^^^^^^^^^^^^^^^^^^^^^^^^^^^^^^^^^^^^^^^^^^^^^^^^^^^
  File "/Users/kaushalprajapati/Desktop/Development/BiD_Indian_BT_startups/src/biotech_pipeline/agents/validation_agent.py", line 115, in _validate_entity_list
    validation_results = self.validator.validate_entity(entity_type, entity_data)
                         ^^^^^^^^^^^^^^^^^^^^^^^^^^^^^^^^^^^^^^^^^^^^^^^^^^^^^^^^
  File "/Users/kaushalprajapati/Desktop/Development/BiD_Indian_BT_startups/src/biotech_pipeline/processors/validator.py", line 317, in validate_entity
    raise ValidationError(
src.biotech_pipeline.utils.exceptions.ValidationError: Unknown entity type: people
2025-08-11 12:24:00,976 | src.biotech_pipeline.pipeline.etl_orchestrator | ERROR | Validation agent crashed for BIRAC/CCAMP01675/BIG-19/21: Unknown entity type: people
Traceback (most recent call last):
  File "/Users/kaushalprajapati/Desktop/Development/BiD_Indian_BT_startups/src/biotech_pipeline/pipeline/etl_orchestrator.py", line 72, in run
    valid, report = validation_agent.validate_complete_profile(bid, payloads)
                    ^^^^^^^^^^^^^^^^^^^^^^^^^^^^^^^^^^^^^^^^^^^^^^^^^^^^^^^^^
  File "/Users/kaushalprajapati/Desktop/Development/BiD_Indian_BT_startups/src/biotech_pipeline/utils/logger.py", line 59, in wrapper
    result = func(*args, **kwargs)
             ^^^^^^^^^^^^^^^^^^^^^
  File "/Users/kaushalprajapati/Desktop/Development/BiD_Indian_BT_startups/src/biotech_pipeline/agents/validation_agent.py", line 63, in validate_complete_profile
    entity_results = self._validate_entity_list(entity_type, entity_data_list)
                     ^^^^^^^^^^^^^^^^^^^^^^^^^^^^^^^^^^^^^^^^^^^^^^^^^^^^^^^^^
  File "/Users/kaushalprajapati/Desktop/Development/BiD_Indian_BT_startups/src/biotech_pipeline/agents/validation_agent.py", line 115, in _validate_entity_list
    validation_results = self.validator.validate_entity(entity_type, entity_data)
                         ^^^^^^^^^^^^^^^^^^^^^^^^^^^^^^^^^^^^^^^^^^^^^^^^^^^^^^^^
  File "/Users/kaushalprajapati/Desktop/Development/BiD_Indian_BT_startups/src/biotech_pipeline/processors/validator.py", line 317, in validate_entity
    raise ValidationError(
src.biotech_pipeline.utils.exceptions.ValidationError: Unknown entity type: people
2025-08-11 12:25:37,538 | src.biotech_pipeline.extractors.base_extractor | ERROR | Max retries exceeded for _fetch_serper: Serper API error
2025-08-11 12:26:31,606 | src.biotech_pipeline.extractors.base_extractor | ERROR | Max retries exceeded for _fetch_serper: Serper API error
2025-08-11 12:27:23,319 | src.biotech_pipeline.extractors.base_extractor | ERROR | Max retries exceeded for _fetch_serper: Serper API error
2025-08-11 12:28:12,059 | src.biotech_pipeline.extractors.website_scraper | ERROR | WebsiteExtractor network error: HTTPSConnectionPool(host='www.cancrie.com', port=443): Max retries exceeded with url: / (Caused by ConnectTimeoutError(<urllib3.connection.HTTPSConnection object at 0x11b615040>, 'Connection to www.cancrie.com timed out. (connect timeout=10)'))
2025-08-11 12:28:32,746 | src.biotech_pipeline.extractors.base_extractor | ERROR | Max retries exceeded for _fetch_serper: Serper API error
2025-08-11 12:28:33,569 | src.biotech_pipeline.agents.validation_agent | ERROR | Operation failed: src.biotech_pipeline.agents.validation_agent.validate_complete_profile (duration: 0.000s) - Error: Unknown entity type: patents
Traceback (most recent call last):
  File "/Users/kaushalprajapati/Desktop/Development/BiD_Indian_BT_startups/src/biotech_pipeline/utils/logger.py", line 59, in wrapper
    result = func(*args, **kwargs)
             ^^^^^^^^^^^^^^^^^^^^^
  File "/Users/kaushalprajapati/Desktop/Development/BiD_Indian_BT_startups/src/biotech_pipeline/agents/validation_agent.py", line 63, in validate_complete_profile
    entity_results = self._validate_entity_list(entity_type, entity_data_list)
                     ^^^^^^^^^^^^^^^^^^^^^^^^^^^^^^^^^^^^^^^^^^^^^^^^^^^^^^^^^
  File "/Users/kaushalprajapati/Desktop/Development/BiD_Indian_BT_startups/src/biotech_pipeline/agents/validation_agent.py", line 115, in _validate_entity_list
    validation_results = self.validator.validate_entity(entity_type, entity_data)
                         ^^^^^^^^^^^^^^^^^^^^^^^^^^^^^^^^^^^^^^^^^^^^^^^^^^^^^^^^
  File "/Users/kaushalprajapati/Desktop/Development/BiD_Indian_BT_startups/src/biotech_pipeline/processors/validator.py", line 374, in validate_entity
    raise ValidationError(
src.biotech_pipeline.utils.exceptions.ValidationError: Unknown entity type: patents
2025-08-11 12:28:33,571 | src.biotech_pipeline.pipeline.etl_orchestrator | ERROR | Validation agent crashed for BIRAC/IKP01696/BIG-22/23: Unknown entity type: patents
Traceback (most recent call last):
  File "/Users/kaushalprajapati/Desktop/Development/BiD_Indian_BT_startups/src/biotech_pipeline/pipeline/etl_orchestrator.py", line 72, in run
    valid, report = validation_agent.validate_complete_profile(bid, payloads)
                    ^^^^^^^^^^^^^^^^^^^^^^^^^^^^^^^^^^^^^^^^^^^^^^^^^^^^^^^^^
  File "/Users/kaushalprajapati/Desktop/Development/BiD_Indian_BT_startups/src/biotech_pipeline/utils/logger.py", line 59, in wrapper
    result = func(*args, **kwargs)
             ^^^^^^^^^^^^^^^^^^^^^
  File "/Users/kaushalprajapati/Desktop/Development/BiD_Indian_BT_startups/src/biotech_pipeline/agents/validation_agent.py", line 63, in validate_complete_profile
    entity_results = self._validate_entity_list(entity_type, entity_data_list)
                     ^^^^^^^^^^^^^^^^^^^^^^^^^^^^^^^^^^^^^^^^^^^^^^^^^^^^^^^^^
  File "/Users/kaushalprajapati/Desktop/Development/BiD_Indian_BT_startups/src/biotech_pipeline/agents/validation_agent.py", line 115, in _validate_entity_list
    validation_results = self.validator.validate_entity(entity_type, entity_data)
                         ^^^^^^^^^^^^^^^^^^^^^^^^^^^^^^^^^^^^^^^^^^^^^^^^^^^^^^^^
  File "/Users/kaushalprajapati/Desktop/Development/BiD_Indian_BT_startups/src/biotech_pipeline/processors/validator.py", line 374, in validate_entity
    raise ValidationError(
src.biotech_pipeline.utils.exceptions.ValidationError: Unknown entity type: patents
2025-08-11 12:29:20,386 | src.biotech_pipeline.extractors.base_extractor | ERROR | Max retries exceeded for _fetch_serper: Serper API error
2025-08-11 12:30:08,903 | src.biotech_pipeline.extractors.base_extractor | ERROR | Max retries exceeded for _fetch_serper: Serper API error
2025-08-11 12:31:04,300 | src.biotech_pipeline.extractors.base_extractor | ERROR | Max retries exceeded for _fetch_serper: Serper API error
2025-08-11 12:31:05,133 | src.biotech_pipeline.pipeline.etl_orchestrator | ERROR | ETL error for BIRAC/KIIT01604/BIG-20/22: Company load failed: (psycopg2.errors.UniqueViolation) duplicate key value violates unique constraint "companies_cin_key"
DETAIL:  Key (cin)=(U74999MH2018PTC356777) already exists.

[SQL: UPDATE companies SET original_awardee=%(original_awardee)s, website_url=%(website_url)s, cin=%(cin)s, location=%(location)s, mca_status=%(mca_status)s, data_quality_score=%(data_quality_score)s, updated_at=%(updated_at)s WHERE companies.big_award_id = %(companies_big_award_id)s]
[parameters: {'original_awardee': ('Individual awardee if different from company', 1), 'website_url': 'https://www.inofinity.com', 'cin': 'U74999MH2018PTC356777', 'location': 'Bangalore, Karnataka, India', 'mca_status': ('Active', 1), 'data_quality_score': 1.0, 'updated_at': datetime.datetime(2025, 8, 11, 7, 1, 5, 129811), 'companies_big_award_id': 'BIRAC/KIIT01604/BIG-20/22'}]
(Background on this error at: https://sqlalche.me/e/20/gkpj)
Traceback (most recent call last):
  File "/Users/kaushalprajapati/Desktop/Development/BiD_Indian_BT_startups/.venv/lib/python3.12/site-packages/sqlalchemy/engine/base.py", line 1963, in _exec_single_context
    self.dialect.do_execute(
  File "/Users/kaushalprajapati/Desktop/Development/BiD_Indian_BT_startups/.venv/lib/python3.12/site-packages/sqlalchemy/engine/default.py", line 943, in do_execute
    cursor.execute(statement, parameters)
psycopg2.errors.UniqueViolation: duplicate key value violates unique constraint "companies_cin_key"
DETAIL:  Key (cin)=(U74999MH2018PTC356777) already exists.


The above exception was the direct cause of the following exception:

Traceback (most recent call last):
  File "/Users/kaushalprajapati/Desktop/Development/BiD_Indian_BT_startups/src/biotech_pipeline/loaders/postgress_loader.py", line 31, in load_companies
    session.flush()
  File "/Users/kaushalprajapati/Desktop/Development/BiD_Indian_BT_startups/.venv/lib/python3.12/site-packages/sqlalchemy/orm/session.py", line 4345, in flush
    self._flush(objects)
  File "/Users/kaushalprajapati/Desktop/Development/BiD_Indian_BT_startups/.venv/lib/python3.12/site-packages/sqlalchemy/orm/session.py", line 4480, in _flush
    with util.safe_reraise():
         ^^^^^^^^^^^^^^^^^^^
  File "/Users/kaushalprajapati/Desktop/Development/BiD_Indian_BT_startups/.venv/lib/python3.12/site-packages/sqlalchemy/util/langhelpers.py", line 224, in __exit__
    raise exc_value.with_traceback(exc_tb)
  File "/Users/kaushalprajapati/Desktop/Development/BiD_Indian_BT_startups/.venv/lib/python3.12/site-packages/sqlalchemy/orm/session.py", line 4441, in _flush
    flush_context.execute()
  File "/Users/kaushalprajapati/Desktop/Development/BiD_Indian_BT_startups/.venv/lib/python3.12/site-packages/sqlalchemy/orm/unitofwork.py", line 466, in execute
    rec.execute(self)
  File "/Users/kaushalprajapati/Desktop/Development/BiD_Indian_BT_startups/.venv/lib/python3.12/site-packages/sqlalchemy/orm/unitofwork.py", line 642, in execute
    util.preloaded.orm_persistence.save_obj(
  File "/Users/kaushalprajapati/Desktop/Development/BiD_Indian_BT_startups/.venv/lib/python3.12/site-packages/sqlalchemy/orm/persistence.py", line 85, in save_obj
    _emit_update_statements(
  File "/Users/kaushalprajapati/Desktop/Development/BiD_Indian_BT_startups/.venv/lib/python3.12/site-packages/sqlalchemy/orm/persistence.py", line 912, in _emit_update_statements
    c = connection.execute(
        ^^^^^^^^^^^^^^^^^^^
  File "/Users/kaushalprajapati/Desktop/Development/BiD_Indian_BT_startups/.venv/lib/python3.12/site-packages/sqlalchemy/engine/base.py", line 1415, in execute
    return meth(
           ^^^^^
  File "/Users/kaushalprajapati/Desktop/Development/BiD_Indian_BT_startups/.venv/lib/python3.12/site-packages/sqlalchemy/sql/elements.py", line 523, in _execute_on_connection
    return connection._execute_clauseelement(
           ^^^^^^^^^^^^^^^^^^^^^^^^^^^^^^^^^^
  File "/Users/kaushalprajapati/Desktop/Development/BiD_Indian_BT_startups/.venv/lib/python3.12/site-packages/sqlalchemy/engine/base.py", line 1637, in _execute_clauseelement
    ret = self._execute_context(
          ^^^^^^^^^^^^^^^^^^^^^^
  File "/Users/kaushalprajapati/Desktop/Development/BiD_Indian_BT_startups/.venv/lib/python3.12/site-packages/sqlalchemy/engine/base.py", line 1842, in _execute_context
    return self._exec_single_context(
           ^^^^^^^^^^^^^^^^^^^^^^^^^^
  File "/Users/kaushalprajapati/Desktop/Development/BiD_Indian_BT_startups/.venv/lib/python3.12/site-packages/sqlalchemy/engine/base.py", line 1982, in _exec_single_context
    self._handle_dbapi_exception(
  File "/Users/kaushalprajapati/Desktop/Development/BiD_Indian_BT_startups/.venv/lib/python3.12/site-packages/sqlalchemy/engine/base.py", line 2351, in _handle_dbapi_exception
    raise sqlalchemy_exception.with_traceback(exc_info[2]) from e
  File "/Users/kaushalprajapati/Desktop/Development/BiD_Indian_BT_startups/.venv/lib/python3.12/site-packages/sqlalchemy/engine/base.py", line 1963, in _exec_single_context
    self.dialect.do_execute(
  File "/Users/kaushalprajapati/Desktop/Development/BiD_Indian_BT_startups/.venv/lib/python3.12/site-packages/sqlalchemy/engine/default.py", line 943, in do_execute
    cursor.execute(statement, parameters)
sqlalchemy.exc.IntegrityError: (psycopg2.errors.UniqueViolation) duplicate key value violates unique constraint "companies_cin_key"
DETAIL:  Key (cin)=(U74999MH2018PTC356777) already exists.

[SQL: UPDATE companies SET original_awardee=%(original_awardee)s, website_url=%(website_url)s, cin=%(cin)s, location=%(location)s, mca_status=%(mca_status)s, data_quality_score=%(data_quality_score)s, updated_at=%(updated_at)s WHERE companies.big_award_id = %(companies_big_award_id)s]
[parameters: {'original_awardee': ('Individual awardee if different from company', 1), 'website_url': 'https://www.inofinity.com', 'cin': 'U74999MH2018PTC356777', 'location': 'Bangalore, Karnataka, India', 'mca_status': ('Active', 1), 'data_quality_score': 1.0, 'updated_at': datetime.datetime(2025, 8, 11, 7, 1, 5, 129811), 'companies_big_award_id': 'BIRAC/KIIT01604/BIG-20/22'}]
(Background on this error at: https://sqlalche.me/e/20/gkpj)

During handling of the above exception, another exception occurred:

Traceback (most recent call last):
  File "/Users/kaushalprajapati/Desktop/Development/BiD_Indian_BT_startups/src/biotech_pipeline/pipeline/etl_orchestrator.py", line 81, in run
    company_id = self.loader.load_companies(payloads["company"])
                 ^^^^^^^^^^^^^^^^^^^^^^^^^^^^^^^^^^^^^^^^^^^^^^^
  File "/Users/kaushalprajapati/Desktop/Development/BiD_Indian_BT_startups/src/biotech_pipeline/loaders/postgress_loader.py", line 38, in load_companies
    raise LoadingError(f"Company load failed: {e}", table="companies")
src.biotech_pipeline.utils.exceptions.LoadingError: Company load failed: (psycopg2.errors.UniqueViolation) duplicate key value violates unique constraint "companies_cin_key"
DETAIL:  Key (cin)=(U74999MH2018PTC356777) already exists.

[SQL: UPDATE companies SET original_awardee=%(original_awardee)s, website_url=%(website_url)s, cin=%(cin)s, location=%(location)s, mca_status=%(mca_status)s, data_quality_score=%(data_quality_score)s, updated_at=%(updated_at)s WHERE companies.big_award_id = %(companies_big_award_id)s]
[parameters: {'original_awardee': ('Individual awardee if different from company', 1), 'website_url': 'https://www.inofinity.com', 'cin': 'U74999MH2018PTC356777', 'location': 'Bangalore, Karnataka, India', 'mca_status': ('Active', 1), 'data_quality_score': 1.0, 'updated_at': datetime.datetime(2025, 8, 11, 7, 1, 5, 129811), 'companies_big_award_id': 'BIRAC/KIIT01604/BIG-20/22'}]
(Background on this error at: https://sqlalche.me/e/20/gkpj)
2025-08-11 12:31:34,548 | src.biotech_pipeline.extractors.website_scraper | ERROR | WebsiteExtractor network error: HTTPSConnectionPool(host='www.innodxsolutions.com', port=443): Max retries exceeded with url: / (Caused by NameResolutionError("<urllib3.connection.HTTPSConnection object at 0x11c24ca40>: Failed to resolve 'www.innodxsolutions.com' ([Errno 8] nodename nor servname provided, or not known)"))
2025-08-11 12:31:57,448 | src.biotech_pipeline.extractors.base_extractor | ERROR | Max retries exceeded for _fetch_serper: Serper API error
2025-08-11 12:31:58,269 | src.biotech_pipeline.agents.validation_agent | ERROR | Operation failed: src.biotech_pipeline.agents.validation_agent.validate_complete_profile (duration: 0.000s) - Error: Unknown entity type: patents
Traceback (most recent call last):
  File "/Users/kaushalprajapati/Desktop/Development/BiD_Indian_BT_startups/src/biotech_pipeline/utils/logger.py", line 59, in wrapper
    result = func(*args, **kwargs)
             ^^^^^^^^^^^^^^^^^^^^^
  File "/Users/kaushalprajapati/Desktop/Development/BiD_Indian_BT_startups/src/biotech_pipeline/agents/validation_agent.py", line 63, in validate_complete_profile
    entity_results = self._validate_entity_list(entity_type, entity_data_list)
                     ^^^^^^^^^^^^^^^^^^^^^^^^^^^^^^^^^^^^^^^^^^^^^^^^^^^^^^^^^
  File "/Users/kaushalprajapati/Desktop/Development/BiD_Indian_BT_startups/src/biotech_pipeline/agents/validation_agent.py", line 115, in _validate_entity_list
    validation_results = self.validator.validate_entity(entity_type, entity_data)
                         ^^^^^^^^^^^^^^^^^^^^^^^^^^^^^^^^^^^^^^^^^^^^^^^^^^^^^^^^
  File "/Users/kaushalprajapati/Desktop/Development/BiD_Indian_BT_startups/src/biotech_pipeline/processors/validator.py", line 374, in validate_entity
    "log_id": StringValidator("log_id"),
src.biotech_pipeline.utils.exceptions.ValidationError: Unknown entity type: patents
2025-08-11 12:31:58,271 | src.biotech_pipeline.pipeline.etl_orchestrator | ERROR | Validation agent crashed for BIRAC/VENTURE0864/BIG-20/22: Unknown entity type: patents
Traceback (most recent call last):
  File "/Users/kaushalprajapati/Desktop/Development/BiD_Indian_BT_startups/src/biotech_pipeline/pipeline/etl_orchestrator.py", line 72, in run
    valid, report = validation_agent.validate_complete_profile(bid, payloads)
                    ^^^^^^^^^^^^^^^^^^^^^^^^^^^^^^^^^^^^^^^^^^^^^^^^^^^^^^^^^
  File "/Users/kaushalprajapati/Desktop/Development/BiD_Indian_BT_startups/src/biotech_pipeline/utils/logger.py", line 59, in wrapper
    result = func(*args, **kwargs)
             ^^^^^^^^^^^^^^^^^^^^^
  File "/Users/kaushalprajapati/Desktop/Development/BiD_Indian_BT_startups/src/biotech_pipeline/agents/validation_agent.py", line 63, in validate_complete_profile
    entity_results = self._validate_entity_list(entity_type, entity_data_list)
                     ^^^^^^^^^^^^^^^^^^^^^^^^^^^^^^^^^^^^^^^^^^^^^^^^^^^^^^^^^
  File "/Users/kaushalprajapati/Desktop/Development/BiD_Indian_BT_startups/src/biotech_pipeline/agents/validation_agent.py", line 115, in _validate_entity_list
    validation_results = self.validator.validate_entity(entity_type, entity_data)
                         ^^^^^^^^^^^^^^^^^^^^^^^^^^^^^^^^^^^^^^^^^^^^^^^^^^^^^^^^
  File "/Users/kaushalprajapati/Desktop/Development/BiD_Indian_BT_startups/src/biotech_pipeline/processors/validator.py", line 374, in validate_entity
    "log_id": StringValidator("log_id"),
src.biotech_pipeline.utils.exceptions.ValidationError: Unknown entity type: patents
2025-08-11 12:32:52,192 | src.biotech_pipeline.extractors.base_extractor | ERROR | Max retries exceeded for _fetch_serper: Serper API error
2025-08-11 12:32:53,035 | src.biotech_pipeline.agents.validation_agent | ERROR | Operation failed: src.biotech_pipeline.agents.validation_agent.validate_complete_profile (duration: 0.000s) - Error: Unknown entity type: patents
Traceback (most recent call last):
  File "/Users/kaushalprajapati/Desktop/Development/BiD_Indian_BT_startups/src/biotech_pipeline/utils/logger.py", line 59, in wrapper
    result = func(*args, **kwargs)
             ^^^^^^^^^^^^^^^^^^^^^
  File "/Users/kaushalprajapati/Desktop/Development/BiD_Indian_BT_startups/src/biotech_pipeline/agents/validation_agent.py", line 63, in validate_complete_profile
    entity_results = self._validate_entity_list(entity_type, entity_data_list)
                     ^^^^^^^^^^^^^^^^^^^^^^^^^^^^^^^^^^^^^^^^^^^^^^^^^^^^^^^^^
  File "/Users/kaushalprajapati/Desktop/Development/BiD_Indian_BT_startups/src/biotech_pipeline/agents/validation_agent.py", line 115, in _validate_entity_list
    validation_results = self.validator.validate_entity(entity_type, entity_data)
                         ^^^^^^^^^^^^^^^^^^^^^^^^^^^^^^^^^^^^^^^^^^^^^^^^^^^^^^^^
  File "/Users/kaushalprajapati/Desktop/Development/BiD_Indian_BT_startups/src/biotech_pipeline/processors/validator.py", line 374, in validate_entity
    "log_id": StringValidator("log_id"),
src.biotech_pipeline.utils.exceptions.ValidationError: Unknown entity type: patents
2025-08-11 12:32:53,036 | src.biotech_pipeline.pipeline.etl_orchestrator | ERROR | Validation agent crashed for BIRAC/CCAMP01675/BIG-19/21: Unknown entity type: patents
Traceback (most recent call last):
  File "/Users/kaushalprajapati/Desktop/Development/BiD_Indian_BT_startups/src/biotech_pipeline/pipeline/etl_orchestrator.py", line 72, in run
    valid, report = validation_agent.validate_complete_profile(bid, payloads)
                    ^^^^^^^^^^^^^^^^^^^^^^^^^^^^^^^^^^^^^^^^^^^^^^^^^^^^^^^^^
  File "/Users/kaushalprajapati/Desktop/Development/BiD_Indian_BT_startups/src/biotech_pipeline/utils/logger.py", line 59, in wrapper
    result = func(*args, **kwargs)
             ^^^^^^^^^^^^^^^^^^^^^
  File "/Users/kaushalprajapati/Desktop/Development/BiD_Indian_BT_startups/src/biotech_pipeline/agents/validation_agent.py", line 63, in validate_complete_profile
    entity_results = self._validate_entity_list(entity_type, entity_data_list)
                     ^^^^^^^^^^^^^^^^^^^^^^^^^^^^^^^^^^^^^^^^^^^^^^^^^^^^^^^^^
  File "/Users/kaushalprajapati/Desktop/Development/BiD_Indian_BT_startups/src/biotech_pipeline/agents/validation_agent.py", line 115, in _validate_entity_list
    validation_results = self.validator.validate_entity(entity_type, entity_data)
                         ^^^^^^^^^^^^^^^^^^^^^^^^^^^^^^^^^^^^^^^^^^^^^^^^^^^^^^^^
  File "/Users/kaushalprajapati/Desktop/Development/BiD_Indian_BT_startups/src/biotech_pipeline/processors/validator.py", line 374, in validate_entity
    "log_id": StringValidator("log_id"),
src.biotech_pipeline.utils.exceptions.ValidationError: Unknown entity type: patents
2025-08-11 12:33:46,813 | src.biotech_pipeline.extractors.base_extractor | ERROR | Max retries exceeded for _fetch_serper: Serper API error
2025-08-11 12:33:47,744 | src.biotech_pipeline.pipeline.etl_orchestrator | ERROR | ETL error for BIRAC/CCAMP01624/BIG-19/21: Company load failed: (psycopg2.errors.UniqueViolation) duplicate key value violates unique constraint "companies_cin_key"
DETAIL:  Key (cin)=(U74999MH2018PTC356777) already exists.

[SQL: UPDATE companies SET original_awardee=%(original_awardee)s, website_url=%(website_url)s, cin=%(cin)s, location=%(location)s, mca_status=%(mca_status)s, data_quality_score=%(data_quality_score)s, updated_at=%(updated_at)s WHERE companies.big_award_id = %(companies_big_award_id)s]
[parameters: {'original_awardee': ('Individual awardee if different from company', 1), 'website_url': 'https://www.cosmosbiotech.com', 'cin': 'U74999MH2018PTC356777', 'location': 'Bangalore, Karnataka, India', 'mca_status': ('Active', 1), 'data_quality_score': 1.0, 'updated_at': datetime.datetime(2025, 8, 11, 7, 3, 47, 741858), 'companies_big_award_id': 'BIRAC/CCAMP01624/BIG-19/21'}]
(Background on this error at: https://sqlalche.me/e/20/gkpj)
Traceback (most recent call last):
  File "/Users/kaushalprajapati/Desktop/Development/BiD_Indian_BT_startups/.venv/lib/python3.12/site-packages/sqlalchemy/engine/base.py", line 1963, in _exec_single_context
    self.dialect.do_execute(
  File "/Users/kaushalprajapati/Desktop/Development/BiD_Indian_BT_startups/.venv/lib/python3.12/site-packages/sqlalchemy/engine/default.py", line 943, in do_execute
    cursor.execute(statement, parameters)
psycopg2.errors.UniqueViolation: duplicate key value violates unique constraint "companies_cin_key"
DETAIL:  Key (cin)=(U74999MH2018PTC356777) already exists.


The above exception was the direct cause of the following exception:

Traceback (most recent call last):
  File "/Users/kaushalprajapati/Desktop/Development/BiD_Indian_BT_startups/src/biotech_pipeline/loaders/postgress_loader.py", line 31, in load_companies
    session.flush()
  File "/Users/kaushalprajapati/Desktop/Development/BiD_Indian_BT_startups/.venv/lib/python3.12/site-packages/sqlalchemy/orm/session.py", line 4345, in flush
    self._flush(objects)
  File "/Users/kaushalprajapati/Desktop/Development/BiD_Indian_BT_startups/.venv/lib/python3.12/site-packages/sqlalchemy/orm/session.py", line 4480, in _flush
    with util.safe_reraise():
         ^^^^^^^^^^^^^^^^^^^
  File "/Users/kaushalprajapati/Desktop/Development/BiD_Indian_BT_startups/.venv/lib/python3.12/site-packages/sqlalchemy/util/langhelpers.py", line 224, in __exit__
    raise exc_value.with_traceback(exc_tb)
  File "/Users/kaushalprajapati/Desktop/Development/BiD_Indian_BT_startups/.venv/lib/python3.12/site-packages/sqlalchemy/orm/session.py", line 4441, in _flush
    flush_context.execute()
  File "/Users/kaushalprajapati/Desktop/Development/BiD_Indian_BT_startups/.venv/lib/python3.12/site-packages/sqlalchemy/orm/unitofwork.py", line 466, in execute
    rec.execute(self)
  File "/Users/kaushalprajapati/Desktop/Development/BiD_Indian_BT_startups/.venv/lib/python3.12/site-packages/sqlalchemy/orm/unitofwork.py", line 642, in execute
    util.preloaded.orm_persistence.save_obj(
  File "/Users/kaushalprajapati/Desktop/Development/BiD_Indian_BT_startups/.venv/lib/python3.12/site-packages/sqlalchemy/orm/persistence.py", line 85, in save_obj
    _emit_update_statements(
  File "/Users/kaushalprajapati/Desktop/Development/BiD_Indian_BT_startups/.venv/lib/python3.12/site-packages/sqlalchemy/orm/persistence.py", line 912, in _emit_update_statements
    c = connection.execute(
        ^^^^^^^^^^^^^^^^^^^
  File "/Users/kaushalprajapati/Desktop/Development/BiD_Indian_BT_startups/.venv/lib/python3.12/site-packages/sqlalchemy/engine/base.py", line 1415, in execute
    return meth(
           ^^^^^
  File "/Users/kaushalprajapati/Desktop/Development/BiD_Indian_BT_startups/.venv/lib/python3.12/site-packages/sqlalchemy/sql/elements.py", line 523, in _execute_on_connection
    return connection._execute_clauseelement(
           ^^^^^^^^^^^^^^^^^^^^^^^^^^^^^^^^^^
  File "/Users/kaushalprajapati/Desktop/Development/BiD_Indian_BT_startups/.venv/lib/python3.12/site-packages/sqlalchemy/engine/base.py", line 1637, in _execute_clauseelement
    ret = self._execute_context(
          ^^^^^^^^^^^^^^^^^^^^^^
  File "/Users/kaushalprajapati/Desktop/Development/BiD_Indian_BT_startups/.venv/lib/python3.12/site-packages/sqlalchemy/engine/base.py", line 1842, in _execute_context
    return self._exec_single_context(
           ^^^^^^^^^^^^^^^^^^^^^^^^^^
  File "/Users/kaushalprajapati/Desktop/Development/BiD_Indian_BT_startups/.venv/lib/python3.12/site-packages/sqlalchemy/engine/base.py", line 1982, in _exec_single_context
    self._handle_dbapi_exception(
  File "/Users/kaushalprajapati/Desktop/Development/BiD_Indian_BT_startups/.venv/lib/python3.12/site-packages/sqlalchemy/engine/base.py", line 2351, in _handle_dbapi_exception
    raise sqlalchemy_exception.with_traceback(exc_info[2]) from e
  File "/Users/kaushalprajapati/Desktop/Development/BiD_Indian_BT_startups/.venv/lib/python3.12/site-packages/sqlalchemy/engine/base.py", line 1963, in _exec_single_context
    self.dialect.do_execute(
  File "/Users/kaushalprajapati/Desktop/Development/BiD_Indian_BT_startups/.venv/lib/python3.12/site-packages/sqlalchemy/engine/default.py", line 943, in do_execute
    cursor.execute(statement, parameters)
sqlalchemy.exc.IntegrityError: (psycopg2.errors.UniqueViolation) duplicate key value violates unique constraint "companies_cin_key"
DETAIL:  Key (cin)=(U74999MH2018PTC356777) already exists.

[SQL: UPDATE companies SET original_awardee=%(original_awardee)s, website_url=%(website_url)s, cin=%(cin)s, location=%(location)s, mca_status=%(mca_status)s, data_quality_score=%(data_quality_score)s, updated_at=%(updated_at)s WHERE companies.big_award_id = %(companies_big_award_id)s]
[parameters: {'original_awardee': ('Individual awardee if different from company', 1), 'website_url': 'https://www.cosmosbiotech.com', 'cin': 'U74999MH2018PTC356777', 'location': 'Bangalore, Karnataka, India', 'mca_status': ('Active', 1), 'data_quality_score': 1.0, 'updated_at': datetime.datetime(2025, 8, 11, 7, 3, 47, 741858), 'companies_big_award_id': 'BIRAC/CCAMP01624/BIG-19/21'}]
(Background on this error at: https://sqlalche.me/e/20/gkpj)

During handling of the above exception, another exception occurred:

Traceback (most recent call last):
  File "/Users/kaushalprajapati/Desktop/Development/BiD_Indian_BT_startups/src/biotech_pipeline/pipeline/etl_orchestrator.py", line 81, in run
    company_id = self.loader.load_companies(payloads["company"])
                 ^^^^^^^^^^^^^^^^^^^^^^^^^^^^^^^^^^^^^^^^^^^^^^^
  File "/Users/kaushalprajapati/Desktop/Development/BiD_Indian_BT_startups/src/biotech_pipeline/loaders/postgress_loader.py", line 38, in load_companies
    raise LoadingError(f"Company load failed: {e}", table="companies")
src.biotech_pipeline.utils.exceptions.LoadingError: Company load failed: (psycopg2.errors.UniqueViolation) duplicate key value violates unique constraint "companies_cin_key"
DETAIL:  Key (cin)=(U74999MH2018PTC356777) already exists.

[SQL: UPDATE companies SET original_awardee=%(original_awardee)s, website_url=%(website_url)s, cin=%(cin)s, location=%(location)s, mca_status=%(mca_status)s, data_quality_score=%(data_quality_score)s, updated_at=%(updated_at)s WHERE companies.big_award_id = %(companies_big_award_id)s]
[parameters: {'original_awardee': ('Individual awardee if different from company', 1), 'website_url': 'https://www.cosmosbiotech.com', 'cin': 'U74999MH2018PTC356777', 'location': 'Bangalore, Karnataka, India', 'mca_status': ('Active', 1), 'data_quality_score': 1.0, 'updated_at': datetime.datetime(2025, 8, 11, 7, 3, 47, 741858), 'companies_big_award_id': 'BIRAC/CCAMP01624/BIG-19/21'}]
(Background on this error at: https://sqlalche.me/e/20/gkpj)
